Workbook

Sheet raw
A1: recipe_raws
A2: <정창욱 셰프 - 치킨 밀푀유 > ● 재료 닭가슴살, 슬라이스햄, 양파, 양배추, 파프리카, 바게트, 다진마늘, 크림소스, 우유, 통후추, 소금, 토마토소스 ● 조리 방법 1. 파프리카, 양배추, 슬라이스 햄을 썰어서 볶는다. 2. 닭가슴살에 소금, 후추를 뿌린 후 팬에 굽고, 잠시 식힌 후 얇게 포를 뜬다. 3. 포를 뜬 가슴살, 볶은 채소와 햄, 치즈, 토마토소스를 켜켜이 쌓는다. *동시에 작은 프라이팬에 크림과 가루치즈를 붓고 약불에 끓여 놓는다 4. 오븐에 5분간 굽고 홀그레인 머스터드, 크림소스, 구운 바게트를 곁들인다. | K2: 냉장고를 부탁해 시즌 1, 1화
A3: <홍석천 셰프 - 취닭거리> ● 재료 닭죽, 라조장, 취두부, 족발, 버터 ● 조리 방법 1. 살을 발라낸 족발에 버터, 라조장을 넣고 볶는다. 2. 취두부를 팬에서 익힌다. 3. 해동한 닭죽과 볶은 족발, 취두부를 함께 곁들인다.
A4: <최현석 - 닭딸> ● 재료 복분자, 바게트, 닭가슴살, 우유, 레몬즙, 소금, 후추, 마늘 ● 조리 방법 1. 복분자를 가열하다가 우유와 레몬즙을 넣고 졸인다. 2. 바케트는 썰어서 팬에 굽는다. 3. 소금 후추로 간을 한 닭가슴살을 마늘과 함께 굽는다. 4. 구운 닭가슴살에 복분자 소스와 바게트를 함께 곁들인다.
A5: <김풍 셰프 - 어머니 맛 풍족밥> ● 재료 치킨, 족발, 두반장, 라조장, 유자청, 밀가루, 밥 ● 조리 방법 1. 살을 발라낸 치킨, 족발에 두반장, 라조장, 유자청 을 넣고 볶는다. 2. 어느 정도 볶다가 밀가루(또는 녹말)를 물에 풀어 좀 더 볶아내면 완성. 3. 뜨거운 밥에 끼얹어 먹는다.
A6: <샘킴 셰프 - 치킨 요로케> ● 재료 닭가슴살, 소금, 후추, 밀가루, 양파, 햄, 토마토 소스, 파마산 치즈, 모짜렐라 치츠, 올리브유 ● 조리 방법 1. 얇게 저민 닭가슴살에 소금, 후추를 뿌리고 밀가루를 묻혀 굽는다. 2. 잘게 썰은 양파와 슬라이스 햄을 함께 볶는다. 3. 토마토 소스에 구운 닭가슴살, 파마산 치즈, 모짜렐라 치즈를 넣고 가열한다. 4. 마지막으로 올리브유를 뿌려준다.
A7: <미카엘 셰프 - 포크 미트볼> ● 재료 김치, 달걀, 햄, 밥 ● 조리 방법 1. 믹서에 갈은 김치와 달걀 물을 섞어서 스크램블을 만든다. 2. 갈은 통조림 햄을 넓게 편 후 1을 넣고 말아준다. 3. 겉에 달걀 물을 뭍이고 팬에서 익혀준다. 4. 접시에 밥과 함께 곁들여 낸다.
A8: <홍석천 셰프 - 만두부인 육수터졌네> ● 재료 냉동만두, 사골육수, 토마토, 발사믹 소스, 버터, 다진마늘, 고추냉이, 올리브오일, 프로슈토햄, 그뤼에르 치즈 ● 조리 방법 ① 뜨거운 팬에 올리브 오일을 두르고 다진 마늘을 볶다가 냉동만두를 굽는다. ② 겉은 바삭하게 구운 다음 버터를 조금 넣고 사골육수를 넣어 졸인다. ③ 졸여지면 발사믹 소스와 고추냉이, 토마토를 함께 넣어 볶는다. ④ 접시에 만두, 토마토 순으로 올리고 프로슈토 햄과 그뤼에르 치즈를 위에 토핑한다. | K8: 냉장고를 부탁해 시즌 1, 2화
A9: <정창욱 셰프 - 심쿵 오믈렛> ● 재료 달걀, 연어, 양파잼, 버터, 브로콜리, 소금, 후추, 케찹 ● 조리 방법 ① 달걀을 풀어놓는다. ② 프라이팬에 오일을 두르고 소금 후추 간을 한 연어를 굽는다. ③ 양파잼과 다진 브로콜리를 넣고 함께 굽는다. ④ 버터를 두른 팬에 풀어놓은 계란을 넣어 반숙으로 익힌다. (* 스크램블 에그 만들 듯이 약간 저어주며 익힌다) ⑤ 반숙으로 익힌 오믈렛에 구운 연어와 야채를 넣고 반으로 접는다. ⑥ 접시에 올리고 케찹을 뿌린다.
A10: <샘킴 셰프 - 엔초비 파스타> ● 재료 파스타면, 바게트빵, 올리브오일, 파슬리, 다진마늘, 애호박, 페페로치노, 엔초비 ● 조리 방법 ① 올리브 오일에 파슬리와 다진 마늘, 찢은 바게트 빵을 섞어 프라이팬에 굽는다. ② 끓는 물에 파스타면을 삶는다. ③ 프라이팬에 올리브 오일을 두르고 애호박, 엔초비, 페페로치노, 파슬리를 넣어 볶는다. ④ 익은 파스타면을 팬으로 옮겨 모든 재료를 함께 볶는다. (기호에 따라 버터를 조금 넣는다.)
A11: <김풍 셰프 - 고기와 썸타는 떡국떡 삼합> ● 재료 맥주, 삼겹살, 김치, 케찹, 고추장, 방울토마토, 떡국떡, 올리브오일 ● 조리 방법 ① 맥주와 삼겹살을 한 번에 넣고 삶는다. ② 들기름 두른 팬에 김치를 볶다가 방울토마토 간 것, 케찹, 고추장을 넣고 볶는다. ③ 기름 두른 팬에 떡국떡을 굽는다. ④ 접시에 적당한 크기로 자른 삼겹살과 김치, 구운 떡국떡을 담아낸다.
A12: <최현석 셰프 - 와닭> ● 재료 생닭, 마늘, 양파, 아티초크, 토마토 소스, 적포도, 사골육수 ● 조리 방법 ① 생닭을 해체한다. (껍질과 뼈는 사용하지 않는다.) ② 양파를 채 썰고, 마늘을 편 썬다. ③ 팬에 오일을 두르고 해체한 닭을 굽는다. ④ 다른 팬에 마늘과 양파를 넣고 볶다가 아티초크를 넣어 함께 볶는다. ⑤ 닭을 굽던 팬에 토마토 소스와 야채들을 넣어 함께 볶는다. ⑥ 적포도의 씨를 발라 프라이팬에 볶다가 모든재료를 함께 볶고 사골육수를 조금 넣어 익힌다.
A13: <미카엘 셰프 - 브로콜리 치킨> ● 재료 닭가슴살, 브로콜리, 슬라이스 치즈, 파프리카, 방울토마토, 버터, 소금, 후추 ● 조리 방법 ① 브로콜리를 잘라서 소금 넣은 물에 데친 후 다진다. ② 방울토마토를 반으로 자르고 파프리카를 채썬다. ③ 닭가슴살을 반으로 갈라 소금 후추 간을 한 후 데친 브로콜리와 치즈를 넣고 이쑤시개로 고정해 굽는다. ④ 같은 팬에 파프리카와 방울토마토를 넣어 함께 익힌다. ⑤ 버터를 조금 넣고 물을 약간 부어 뚜껑을 덮어 익힌다. ⑥ 고춧가루를 조금 뿌린다.
A14: <정창욱 셰프 - 삼겹살 플레이트> ● 재료 삼겹살, 양파, 알배추, 밥, 버터, 통마늘, 간장, 미림, 청주, 커피가루, 다진 마늘, 다진 생강 ● 조리 방법 ① 삼겹살을 썰어서 소금후추 간을 해서 굽는다. ② 다른 팬에 버터와 통마늘, 채 썬 양파를 넣어 볶다가 간장, 미림, 다진생강, 다진마늘, 커피가루를 넣어 끓인다. ③ 삼겹살에 청주를 넣어 끓이다가 건져 야채와 함께 섞는다 ④ 채 썬 알배추를 듬뿍 넣고 뚜껑을 덮어 숨을 죽인다. ⑤ 아이스크림 스쿱으로 밥을 담고 익은 고기와 채소를 얹어 낸다. | K14: 냉장고를 부탁해 시즌 1, 3화
A15: <최현석 셰프 - 강남비빔면> ● 재료 생칼국수면, 삼겹살, 새우젓, 고추장, 딸기잼, 참기름, 고추냉이 ● 조리 방법 ① 삼겹살을 잘게 썰어서 기름에 바삭하게 튀긴다 ② 고추장과 딸기잼, 참기름, 고추냉이를 섞는다 ③ 끓는 물에 칼국수면을 삶는다 (넘칠 때쯤 찬물을 한 번 넣어 쫄깃함을 더한다) ④ 물에 씻은 새우젓을 기름에 튀긴다 ⑤ 익은 면을 찬물에 씻고 소스와 버무려 접시에 담은 뒤 튀긴 삼겹살과 새우젓, 오렌지를 토핑한다.
A16: <샘킴 셰프 - 나 또 브리또> ● 재료 냉동새우 볶음밥, 소고기, 간장, 미림, 다진 마늘, 후추, 대파, 타이 칠리소스, 낫토, 버터, 플레인 요거트, 레몬즙 ● 조리 방법 ① 간장, 미림, 다진마늘, 후추, 어슷 썬 대파, 타이칠리소스, 낫토를 섞은 것에 샤브샤브용 고기를 넣어 재운다. ② 냉동새우볶음밥에 낫토, 버터를 넣어 볶는다. ③ 플레인 요거트와 레몬즙을 섞어 사워크림을 만들고 낫토를 잘게 다져 넣는다. ④ 또띠아를 팬에 굽고 다른 팬에 고기를 익힌다. ⑤ 또띠아 위에 볶음밥과 고기, 크림과 어슷썬 파를 얹어 낸다. | K16: 냉장고를 부탁해 시즌 1, 4화
A17: <김풍 셰프 - 갸루상 케이크> ● 재료 또띠아, 달걀, 설탕, 우유, 바닐라 아이스크림, 밀가루, 딸기 ● 조리 방법 ① 달걀의 흰자와 노른자를 분리한다. ② 노른자 2개와 설탕, 우유, 바닐라 아이스크림, 밀가루를 넣어 섞고 커스터드 크림이 될 때까지 전자렌지에 3분 간격으로 돌린다. ③ 또띠아를 6등분 해 기름에 튀겨낸다. ④ 튀긴 또띠아 위에 커스터드 크림을 층층이 올리고 반으로 자른 딸기를 토핑한다.
A18: <미카엘 셰프 - PLETKA> ● 재료 돼지고기 안심, 베이컨, 김치, 밥, 당근, 양파, 소주, 부추 ● 조리 방법 ① 길게 썬 돼지고기 안심과 베이컨의 윗부분을 이쑤시개로 고정한 후 머리땋 듯 땋고 끝부분도 이쑤시개로 고정해 팬에 굽는다. ② 소주를 부어 잡내를 날린다. ③ 김치, 양파, 당근을 잘게 썰어 같은 팬에 넣고 볶다가 물을 붓고 뚜껑을 덮는다. ④ 접시에 고기를 올리고 밥과 김치를 쌓아서 낸 후 다진 부추로 토핑한다.
A19: <홍석천 셰프 - 다 줄게라면> ● 재료 삼겹살, 복분자주, 김치, 어묵 통조림, 알배추, 라면, 매운 미소소스 ● 조리 방법 ① 복분자주에 재운 삼겹살을 길게 찢은 김치와 함께 말아 부추로 고정한 후 팬에 굽는다. ② 물과 어묵통조림과 매운미소소스, 큼직하게 썬 알배추를 넣고 끓인다. ③ 면을 넣어 끓인다. ④ 접시에 끓인 라면을 담고 김치말이 삼겹살을 얹어서 낸다.
A20: <정창욱 셰프 - 우리집에 오.새.요> ● 재료 청주, 미림, 양조간장, 국수장국, 오징어, 칵테일 새우, 다진 마늘, 당근, 양파, 박력분, 전분, 얼음, 대파, 무 ● 조리 방법 1. 청주, 미림, 양조간장, 국수장국을 끓여 소스를 만든다. 2. 오징어는 간장, 다진 마늘, 청주, 미림에 담가 간을 한다. 3. 채썬 채소와 칵테일 새우, 박력분, 전분, 얼음을 넣어 반죽을 한다. (* 반죽 후 얼음은 꼭 제거한다.) 4. 달궈진 기름에 반죽을 한국자씩 넣고 튀긴다. 5. 간을 한 오징어에 전분을 묻혀 튀긴다. 6. 그릇에 밥과 어슷썬 대파, 완성된 튀김과 갈은 무, 소스를 올려낸다. | K20: 냉장고를 부탁해 시즌 1, 5화
A21: <샘킴 셰프 - Mr.콩chu~♥> ● 재료 버터, 밀가루, 두유, 두부, 전분, 계피맛 쿠키, 설탕, 초콜릿 ● 조리 방법 1. 두부의 물기를 제거한다. 2. 버터를 녹이고 밀가루, 두유를 넣어 소스를 만든다. 3. 계피맛 쿠키를 믹서에 갈고 설탕을 섞어둔다 4. 깍뚝 썬 두부에 전분을 묻혀 튀긴다. 5. 튀긴 두부에 계피설탕가루를 입힌다. 6. 그릇에 두유소스와 두부츄러스, 바닐라 아이스크림, 다진 초콜릿을 토핑한다.
A22: <최현석 셰프 - For덕> ● 재료 가지, 계란흰자 통조림, 토마토, 파프리카, 고추장아찌, 토마토 소스, 올리브유, 소금, 후추 ● 조리 방법 ① 가지를 길게 썰어 올리브유를 두른 팬에 양면을 굽는다. ② 토마토는 열십자로 칼집을 내어 끓는 물에 데쳐 껍질을 벗긴다. ③ 적당한 크기로 썬 토마토와 다진 파프리카, 양파, 사과, 고추장아찌를 냄비에 넣고 으깨 소스를 만든다. ④ 토마토 소스를 넣어 풍미를 더한다. ⑤ 익은 가지를 격자 모양으로 놓고 소금 후추를 뿌린 후, 가운데 계란흰자 통조림을 넣어 감싼다. (* 비닐을 이용하면 좀 더 쉽게 모양을 잡을 수 있다.) ⑥ 모양이 잡힌 가지를 올리브유를 두른 팬에 한 번 더 익힌다. ⑦ 접시에 소스와 가지를 담아 낸다. | K22: 냉장고를 부탁해 시즌 1, 6화
A23: <미카엘 셰프 - 프로틴 스틱> ● 재료 계란흰자 통조림, 닭가슴살, 파프리카, 양파, 당근, 사과, 견과류, 대파, 식초, 올리브유 ● 조리 방법 ① 계란 흰자 통조림과 닭가슴살, 파프리카, 양파를 깍둑썰기 해 꼬치에 끼운다. ② 꼬치에 소금, 후추를 두르고 그릴팬에 굽는다. ③ 당근, 사과를 강판에 채썰고, 식초, 올리브유, 다진 견과류를 뿌린다. ④ 접시에 샐러드를 깔고 꼬치를 위에 낸다.
A24: <홍석천 셰프 - 불닭 소시지> ● 재료 소시지, 매운라면 소스, 당면라면, 청양고추, 상추 ● 조리 방법 ① 소시지를 끓는 물에 데쳐 기름기를 제거하고 적당한 크기로 썬다. ② 당면라면의 면을 끓는 물에 데쳐 찬물에 헹군 후, 매운라면 소스, 다진 청양고추에 버무린다. ③ 꼬치에 소시지를 꽂고, 양념한 면을 감는다. ④ 접시에 꼬치를 놓고 상추를 곁들여 낸다.
A25: <김풍 셰프 - 매우면 참치 & 쏘루아밀크> ● 재료 참치, 식빵, 토마토, 버터, 고춧가루, 소금, 소주, 인스턴트 커피, 흰우유 ● 조리 방법 ① 식빵을 토스트기에 굽는다. ② 버터를 두른 팬에 기름 뺀 참치와 믹서에 간 토마토, 고춧가루를 넣고 끓인다. ③ 얼음을 담은 잔에 소주, 설탕, 인스턴트 커피 섞은 것을 넣고, 흰우유를 넣어 층을 낸다. ④ 구운 식빵을 적당한 크기로 자르고 참치 양념을 얹어낸다.
A26: <정창욱 셰프 - 삼층돈탑> ● 재료 알배추, 대파, 목살, 다진 고추 장아찌, 설탕, 스테이크 소스, 올리고당 ● 조리 방법 1. 알배추는 먹기 좋은 크기로 썰어둔다. 2. 대파는 채썰고, 마늘은 편으로 썰어둔다. 돼지고기는 먹기 좋은 크기로 자른다. 3. 전자레인지용 그릇에 알배추 - 채 썬 대파 - 돼지고기를 층층이 쌓고 소금 후추 간을 한다. 4. 랩을 두르고 3분 간격으로 렌지에 돌린다. 5. 다진 고추 장아찌와 국물, 설탕을 두른 소스와 스테이크소스, 올리고당을 섞은 소스를 함께 낸다. | K26: 냉장고를 부탁해 시즌 1, 7화
A27: <김풍 셰프 - 엠티 오후의 라면> ● 재료 라면, 밀가루, 쇠고기 스프, 오징어, 계란 ● 조리 방법 1. 끓는 물에 밀가루와 쇠고기 스프, 라면스프를 넣고 끓인다. 2. 채 썬 오징어와 면, 건더기 스프를 넣고 끓인다. 3. 계란 푼 것을 라면에 두른다. 4. 총각김치를 곁들여 낸다.
A28: <최현석 셰프 - 봉선아 시집가자미> ● 재료 가자미, 양송이 버섯, 복분자 엑기스, 대파, 소금, 후추, 밀가루, 화이트 와인, 버터 ● 조리 방법 1. 팬 하나에 대파를 잘게 썰어 볶고, 다른 팬에는 양송이 버섯에 소금 후추 간을 해 볶는다. 2. 가자미는 껍질을 벗기고 뼈를 발라낸다. 3. 가자미에 소금 후추 간을 하고 밀가루를 뭍혀 올리브유를 두른 팬에 굽는다. 4. 가자미를 굽는 팬에 화이트와인과 복분자 엑기스를 부어 졸인다. 5. 그릇에 볶은 대파와 버섯을 놓고 그 위에 구운 가자미를 올린다. 6. 가자미 육즙이 남은 팬에 버터를 넣어 소스를 만든다.
A29: <샘킴 - 스키니 신> ● 재료 키조개 관자, 단감, 양상추, 양파, 고구마, 감자, 올리브유 ● 조리 방법 1. 감자를 삶는다. 2. 관자는 물기를 제거하고, 올리브유는 냄비에 넣고 데운다. 3. 관자는 얇게 썰어두고, 살짝 감자를 강판에 간다 4. 볼에 다진 양상추, 단감, 고구마를 넣고 샐러드를 만든다. 5. 감자와 다진 양파로 전을 부친다. 6. 달군 올리브유를 관자에 부어 익힌다. 7. 접시에 감자양파전, 샐러드, 관자를 얹어 낸다.
A30: <미카엘 - 파티비프> ● 재료 밥, 등심, 느타리 버섯, 양송이 버섯, 양상추, 양파, 총각김치, 쌈장, 생크림 ● 조리 방법 1. 청고추에 칼집을 내고 그릴팬에 굽는다. 2. 고기와 양파는 채썰고 양송이 버섯도 편으로 썰어 팬에 볶는다. 3. 2에 고기에 쌈장과 생크림을 넣고 볶는다. 4. 3에 다진 총각김치를 넣고 후추를 뿌린다. 5. 접시에 밥을 놓고 주위에 볶은 고기를 얹는다. 6. 중앙에 총각김치를 올린다.
A31: <홍석천 - 아이러브유부> ● 재료 삼겹살, 생크림, 달걀, 통마늘, 잣, 양파, 두반장, 굴소스, 고추장아찌 국물, 핫소스 ● 조리 방법 1. 삼겹살, 생크림, 달걀 흰자, 마늘 2쪽을 믹서기에 넣고 간다. 2. 간 고기에 잣, 두반장, 굴소스를 넣고 섞는다. 3. 양파와 물에 씻은 고추장아찌를 다져 섞는다. 4. 유부의 속을 채우고 삶는다. 5. 고추 장아찌 국물과 핫소스, 볶은 다진 마늘을 섞어 소스를 만들어 함께 낸다.
A32: <최현석 셰프 - 곤약 봉골레 곤봉> ● 재료 곤약, 파프리카, 바지락, 올리브 오일, 마늘, 소금, 후추 ● 조리 방법 1. 가스레인지 위에 파프리카를 올리고 표면을 태운다. 2. 곤약을 얇게 국수처럼 썬다. (실곤약 대체 가능) 3. 바지락 반은 육수를 내고 반은 살을 발라둔다. 4. 표면을 태운 파프리카의 껍질을 벗기고 얇게 채썬다. 5. 올리브유에 다진 마늘을 볶다가 바지락과 소금 후추를 뿌리고 볶는다. 6. 채 썬 곤약과 파프리카를 넣어 볶다가 육수를 부어 끓인다. | K32: 냉장고를 부탁해 시즌 1, 8화
A33: <홍석천 셰프 - 렛잇컵> ● 재료 찐고구마, 두유, 딸기, 키위, 사과, 홍시, 플레인 요거트, 생고구마 ● 조리 방법 1. 찐 고구마의 껍질을 벗기고 으깬 후, 두유를 섞어 농도를 맞춘다. 2. 각종 과일을 먹기 좋은 크기로 썰어 둔다. 3. 와인잔에 찐 고구마와 과일을 겹겹이 쌓는다. 4. 플레인 요거트와 복분자 원액을 넣는다. 5. 생고구마를 썰어 스틱을 만들고 홍시와 플레인 요거트로 소스을 만들어 함께 낸다.
A34: <샘킴 셰프 - 마이 러블리 튀밥> ● 재료 파프리카, 버섯, 양파, 명란젓, 대파, 즉석밥, 참기름, 치즈, 소금, 후추, 올리브유, 마늘, 블랙올리브, 홍고추, 방울토마토, 토마토소스, 밀가루, 달걀, 빵가루, 식용유, 파슬리 ● 조리 방법 1. 파프리카, 버섯, 양파를 다지고 올리브유를 두른 팬에 볶는다. 2. 명란젓에 다진 대파를 넣고, 볶은 채소, 즉석밥, 참기름을 넣고 함께 섞는다. 3. 팬에 올리브유와 마늘, 블랙올리브, 홍고추, 방울토마토, 토마토 소스를 넣어 소스를 만든다. 4. 밥을 뭉칠 때 속에 치즈를 넣고 밀가루, 달걀물, 빵가루 순으로 옷을 입힌다. 5. 달군 기름에 뭉친 밥을 넣어 튀긴다. 6. 토마토소스 위에 튀긴 밥을 올리고 파슬리와 올리브유를 뿌려서 낸다. | K34: 냉장고를 부탁해 시즌 1, 9화
A35: <김풍 셰프 - 자투리타타> ● 재료 파프리카, 양파, 버섯, 명란젓, 달걀, 올리브유, 방울토마토, 마늘, 팽이버섯, 베이컨 ● 조리 방법 1. 파프리카, 양파, 버섯 등의 재료는 잘게 다진다. 2. 명란젓을 넣은 달걀물에 치즈를 갈아 넣는다. 3. 올리브유를 두른 팬에 다진 채소와 방울토마토, 다진 마늘, 팽이버섯을 넣고 볶는다. 4. 채소를 볶던 팬에 달걀물을 붓고 호일을 덮어 익힌다. 5. 베이컨을 잘게 썰어 키친타올 사이에 넣고 렌지에 돌려 바삭하게 만든다. 6. 프리타타 위에 베이컨을 놓고 토치로 표면을 익힌다.
A36: <정창욱 셰프 - 괜찮아, 목심이야> ● 재료 돼지고기 목심, 양파, 당근, 양상추, 사과, 전분, 소금, 후추, 오리엔탈 소스, 식초, 설탕 ● 조리 방법 1. 양파, 당근, 사과, 양상추를 가늘게 채 썬다. 2. 오리엔탈 소스에 식초와 설탕을 넣어 끓인 후, 채 썬 양파, 당근과 섞어둔다. 3. 소금, 후추로 밑간을 한 돼지고기 목심을 전분이 고르게 묻도록 섞는다. 4. 끓는 물에 돼지고기 목심을 익힌 후, 건진다. 5. 접시에 고기와 채소를 차례로 얹는다. 6. 채 썬 양상추와 사과를 올리고 소스를 뿌려 완성한다.
A37: <미카엘 셰프 - 마이 스위트 베이비> ● 재료 소고기 등심, 사과, 레드와인, 흑설탕, 소금, 후추 ● 조리 방법 1. 소금, 후추 간을 한 소고기 등심을 팬에 굽는다. 2. 사과를 자르고 씨를 발라 팬에 굽는다. 3. 소고기 등심을 꺼내 놓고 흑설탕과 물에 구운 사과를 졸인다. 4. 등심을 다시 팬에 올리고 레드와인을 부어 좀 더 익힌다. 5. 졸인 사과와 등심을 함께 낸다
A38: <최현석 셰프 - 어란대첩> ● 재료 파스타면(엔젤헤어), 무, 어란, 올리브유, 쯔유, 소금, 후추 ● 조리 방법 1. 무를 얇게 채 썬다. 2. 채 썬 무를 얼음물에 담가 식감을 살린다. 3. 끓는 물에 파스타면을 넣고 삶는다. 4. 익은 파스타면을 얼음물에 넣어 식힌 후 올리브유, 쯔유, 소금, 후추를 넣어 섞는다. 5. 접시에 파스타면과 채썬 무를 차례로 올리고 어란을 갈아 올린다. | K38: 냉장고를 부탁해 시즌 1, 10화
A39: <박준우 셰프 - 뉴타운 달팽이> ● 재료 달팽이, 양파, 버터, 매시드 포테이토 분말, 레드와인, 시금치 ● 조리 방법 1. 팬에 버터, 다진 양파, 소금, 달팽이를 넣고 볶는다. 2. 끓는 물에 매시드 포테이토 분말을 넣고 매시드 포테이토를 만든다. 3. 달팽이를 볶던 팬에 레드와인을 부어 졸인다. 4. 팬에 버터와 시금치를 넣어 볶는다. 5. 접시에 매시드 포테이토를 깔고 달팽이와 양파를 올린 후, 볶은 시금치와 소스를 곁들여 낸다. 6. 마지막으로 다진 홍고추를 올린다.
A40: <홍석천 셰프 - 삼국회담> ● 재료 양갈비, 쌀국수면, 커민, 마늘, 중국 고추소스, 코코넛 밀크, 새우젓, 말린 양파, 피쉬소스, 동치미 국물, 탄산수, 참기름 ● 조리 방법 1. 끓는 물에 쌀국수면을 삶는다. 2. 후추를 뿌린 양갈비를 손질한 후, 커민으로 양념을 한다. 3. 올리브유를 두른 팬에 으깬 마늘과 중국 고추소스를 넣어 볶다가 양갈비를 넣어 굽는다. 4. 믹서기에 코코넛 밀크와 새우젓, 말린 양파를 넣고 갈아 소스를 만든다. 5. 끓인 쌀국수 면을 건져 얼음물에 헹군 후 피쉬소스, 동치미 국물, 탄산수, 참기름을 넣어 국수를 완성한다. 6. 접시에 구운 양갈비와 새우젓 소스를 곁들여 낸다.
...

Sheet ingredient
A1: recipe_title | B1: ingredients_raw
A2: =recipe!C2 -> 치킨 밀푀유 | B2: =IFERROR(__xludf.DUMMYFUNCTION("TRIM( REGEXEXTRACT( raw!A2, ""(?s)●\s*재료(.*)●\s*조리 방법"" ) ) "),"닭가슴살, 슬라이스햄, 양파, 양배추, 파프리카, 바게트, 다진마늘, 크림소스, 우유, 통후추, 소금, 토마토소스") -> 닭가슴살, 슬라이스햄, 양파, 양배추, 파프리카, 바게트, 다진마늘, 크림소스, 우유, 통후추, 소금, 토마토소스
A3: =recipe!C3 -> 취닭거리 | B3: =IFERROR(__xludf.DUMMYFUNCTION("TRIM( REGEXEXTRACT( raw!A3, ""(?s)●\s*재료(.*)●\s*조리 방법"" ) ) "),"닭죽, 라조장, 취두부, 족발, 버터") -> 닭죽, 라조장, 취두부, 족발, 버터
A4: =recipe!C4 -> 닭딸 | B4: =IFERROR(__xludf.DUMMYFUNCTION("TRIM( REGEXEXTRACT( raw!A4, ""(?s)●\s*재료(.*)●\s*조리 방법"" ) ) "),"복분자, 바게트, 닭가슴살, 우유, 레몬즙, 소금, 후추, 마늘") -> 복분자, 바게트, 닭가슴살, 우유, 레몬즙, 소금, 후추, 마늘
A5: =recipe!C5 -> 어머니 맛 풍족밥 | B5: =IFERROR(__xludf.DUMMYFUNCTION("TRIM( REGEXEXTRACT( raw!A5, ""(?s)●\s*재료(.*)●\s*조리 방법"" ) ) "),"치킨, 족발, 두반장, 라조장, 유자청, 밀가루, 밥") -> 치킨, 족발, 두반장, 라조장, 유자청, 밀가루, 밥
A6: =recipe!C6 -> 치킨 요로케 | B6: =IFERROR(__xludf.DUMMYFUNCTION("TRIM( REGEXEXTRACT( raw!A6, ""(?s)●\s*재료(.*)●\s*조리 방법"" ) ) "),"닭가슴살, 소금, 후추, 밀가루, 양파, 햄, 토마토 소스, 파마산 치즈, 모짜렐라 치츠, 올리브유") -> 닭가슴살, 소금, 후추, 밀가루, 양파, 햄, 토마토 소스, 파마산 치즈, 모짜렐라 치츠, 올리브유
A7: =recipe!C7 -> 포크 미트볼 | B7: =IFERROR(__xludf.DUMMYFUNCTION("TRIM( REGEXEXTRACT( raw!A7, ""(?s)●\s*재료(.*)●\s*조리 방법"" ) ) "),"김치, 달걀, 햄, 밥") -> 김치, 달걀, 햄, 밥
A8: =recipe!C8 -> 만두부인 육수터졌네 | B8: =IFERROR(__xludf.DUMMYFUNCTION("TRIM( REGEXEXTRACT( raw!A8, ""(?s)●\s*재료(.*)●\s*조리 방법"" ) ) "),"냉동만두, 사골육수, 토마토, 발사믹 소스, 버터, 다진마늘, 고추냉이, 올리브오일, 프로슈토햄, 그뤼에르 치즈") -> 냉동만두, 사골육수, 토마토, 발사믹 소스, 버터, 다진마늘, 고추냉이, 올리브오일, 프로슈토햄, 그뤼에르 치즈
A9: =recipe!C9 -> 심쿵 오믈렛 | B9: =IFERROR(__xludf.DUMMYFUNCTION("TRIM( REGEXEXTRACT( raw!A9, ""(?s)●\s*재료(.*)●\s*조리 방법"" ) ) "),"달걀, 연어, 양파잼, 버터, 브로콜리, 소금, 후추, 케찹") -> 달걀, 연어, 양파잼, 버터, 브로콜리, 소금, 후추, 케찹
A10: =recipe!C10 -> 엔초비 파스타 | B10: =IFERROR(__xludf.DUMMYFUNCTION("TRIM( REGEXEXTRACT( raw!A10, ""(?s)●\s*재료(.*)●\s*조리 방법"" ) ) "),"파스타면, 바게트빵, 올리브오일, 파슬리, 다진마늘, 애호박, 페페로치노, 엔초비") -> 파스타면, 바게트빵, 올리브오일, 파슬리, 다진마늘, 애호박, 페페로치노, 엔초비
A11: =recipe!C11 -> 고기와 썸타는 떡국떡 삼합 | B11: =IFERROR(__xludf.DUMMYFUNCTION("TRIM( REGEXEXTRACT( raw!A11, ""(?s)●\s*재료(.*)●\s*조리 방법"" ) ) "),"맥주, 삼겹살, 김치, 케찹, 고추장, 방울토마토, 떡국떡, 올리브오일") -> 맥주, 삼겹살, 김치, 케찹, 고추장, 방울토마토, 떡국떡, 올리브오일
A12: =recipe!C12 -> 와닭 | B12: =IFERROR(__xludf.DUMMYFUNCTION("TRIM( REGEXEXTRACT( raw!A12, ""(?s)●\s*재료(.*)●\s*조리 방법"" ) ) "),"생닭, 마늘, 양파, 아티초크, 토마토 소스, 적포도, 사골육수") -> 생닭, 마늘, 양파, 아티초크, 토마토 소스, 적포도, 사골육수
A13: =recipe!C13 -> 브로콜리 치킨 | B13: =IFERROR(__xludf.DUMMYFUNCTION("TRIM( REGEXEXTRACT( raw!A13, ""(?s)●\s*재료(.*)●\s*조리 방법"" ) ) "),"닭가슴살, 브로콜리, 슬라이스 치즈, 파프리카, 방울토마토, 버터, 소금, 후추") -> 닭가슴살, 브로콜리, 슬라이스 치즈, 파프리카, 방울토마토, 버터, 소금, 후추
A14: =recipe!C14 -> 삼겹살 플레이트 | B14: =IFERROR(__xludf.DUMMYFUNCTION("TRIM( REGEXEXTRACT( raw!A14, ""(?s)●\s*재료(.*)●\s*조리 방법"" ) ) "),"삼겹살, 양파, 알배추, 밥, 버터, 통마늘, 간장, 미림, 청주, 커피가루, 다진 마늘, 다진 생강") -> 삼겹살, 양파, 알배추, 밥, 버터, 통마늘, 간장, 미림, 청주, 커피가루, 다진 마늘, 다진 생강
A15: =recipe!C15 -> 강남비빔면 | B15: =IFERROR(__xludf.DUMMYFUNCTION("TRIM( REGEXEXTRACT( raw!A15, ""(?s)●\s*재료(.*)●\s*조리 방법"" ) ) "),"생칼국수면, 삼겹살, 새우젓, 고추장, 딸기잼, 참기름, 고추냉이") -> 생칼국수면, 삼겹살, 새우젓, 고추장, 딸기잼, 참기름, 고추냉이
A16: =recipe!C16 -> 나 또 브리또 | B16: =IFERROR(__xludf.DUMMYFUNCTION("TRIM( REGEXEXTRACT( raw!A16, ""(?s)●\s*재료(.*)●\s*조리 방법"" ) ) "),"냉동새우 볶음밥, 소고기, 간장, 미림, 다진 마늘, 후추, 대파, 타이 칠리소스, 낫토, 버터, 플레인 요거트, 레몬즙") -> 냉동새우 볶음밥, 소고기, 간장, 미림, 다진 마늘, 후추, 대파, 타이 칠리소스, 낫토, 버터, 플레인 요거트, 레몬즙
A17: =recipe!C17 -> 갸루상 케이크 | B17: =IFERROR(__xludf.DUMMYFUNCTION("TRIM( REGEXEXTRACT( raw!A17, ""(?s)●\s*재료(.*)●\s*조리 방법"" ) ) "),"또띠아, 달걀, 설탕, 우유, 바닐라 아이스크림, 밀가루, 딸기") -> 또띠아, 달걀, 설탕, 우유, 바닐라 아이스크림, 밀가루, 딸기
A18: =recipe!C18 -> PLETKA | B18: =IFERROR(__xludf.DUMMYFUNCTION("TRIM( REGEXEXTRACT( raw!A18, ""(?s)●\s*재료(.*)●\s*조리 방법"" ) ) "),"돼지고기 안심, 베이컨, 김치, 밥, 당근, 양파, 소주, 부추") -> 돼지고기 안심, 베이컨, 김치, 밥, 당근, 양파, 소주, 부추
A19: =recipe!C19 -> 다 줄게라면 | B19: =IFERROR(__xludf.DUMMYFUNCTION("TRIM( REGEXEXTRACT( raw!A19, ""(?s)●\s*재료(.*)●\s*조리 방법"" ) ) "),"삼겹살, 복분자주, 김치, 어묵 통조림, 알배추, 라면, 매운 미소소스") -> 삼겹살, 복분자주, 김치, 어묵 통조림, 알배추, 라면, 매운 미소소스
A20: =recipe!C20 -> 우리집에 오.새.요 | B20: =IFERROR(__xludf.DUMMYFUNCTION("TRIM( REGEXEXTRACT( raw!A20, ""(?s)●\s*재료(.*)●\s*조리 방법"" ) ) "),"청주, 미림, 양조간장, 국수장국, 오징어, 칵테일 새우, 다진 마늘, 당근, 양파, 박력분, 전분, 얼음, 대파, 무") -> 청주, 미림, 양조간장, 국수장국, 오징어, 칵테일 새우, 다진 마늘, 당근, 양파, 박력분, 전분, 얼음, 대파, 무
A21: =recipe!C21 -> Mr.콩chu~♥ | B21: =IFERROR(__xludf.DUMMYFUNCTION("TRIM( REGEXEXTRACT( raw!A21, ""(?s)●\s*재료(.*)●\s*조리 방법"" ) ) "),"버터, 밀가루, 두유, 두부, 전분, 계피맛 쿠키, 설탕, 초콜릿") -> 버터, 밀가루, 두유, 두부, 전분, 계피맛 쿠키, 설탕, 초콜릿
A22: =recipe!C22 -> For덕 | B22: =IFERROR(__xludf.DUMMYFUNCTION("TRIM( REGEXEXTRACT( raw!A22, ""(?s)●\s*재료(.*)●\s*조리 방법"" ) ) "),"가지, 계란흰자 통조림, 토마토, 파프리카, 고추장아찌, 토마토 소스, 올리브유, 소금, 후추") -> 가지, 계란흰자 통조림, 토마토, 파프리카, 고추장아찌, 토마토 소스, 올리브유, 소금, 후추
A23: =recipe!C23 -> 프로틴 스틱 | B23: =IFERROR(__xludf.DUMMYFUNCTION("TRIM( REGEXEXTRACT( raw!A23, ""(?s)●\s*재료(.*)●\s*조리 방법"" ) ) "),"계란흰자 통조림, 닭가슴살, 파프리카, 양파, 당근, 사과, 견과류, 대파, 식초, 올리브유") -> 계란흰자 통조림, 닭가슴살, 파프리카, 양파, 당근, 사과, 견과류, 대파, 식초, 올리브유
A24: =recipe!C24 -> 불닭 소시지 | B24: =IFERROR(__xludf.DUMMYFUNCTION("TRIM( REGEXEXTRACT( raw!A24, ""(?s)●\s*재료(.*)●\s*조리 방법"" ) ) "),"소시지, 매운라면 소스, 당면라면, 청양고추, 상추") -> 소시지, 매운라면 소스, 당면라면, 청양고추, 상추
A25: =recipe!C25 -> 매우면 참치 & 쏘루아밀크 | B25: =IFERROR(__xludf.DUMMYFUNCTION("TRIM( REGEXEXTRACT( raw!A25, ""(?s)●\s*재료(.*)●\s*조리 방법"" ) ) "),"참치, 식빵, 토마토, 버터, 고춧가루, 소금, 소주, 인스턴트 커피, 흰우유") -> 참치, 식빵, 토마토, 버터, 고춧가루, 소금, 소주, 인스턴트 커피, 흰우유
A26: =recipe!C26 -> 삼층돈탑 | B26: =IFERROR(__xludf.DUMMYFUNCTION("TRIM( REGEXEXTRACT( raw!A26, ""(?s)●\s*재료(.*)●\s*조리 방법"" ) ) "),"알배추, 대파, 목살, 다진 고추 장아찌, 설탕, 스테이크 소스, 올리고당") -> 알배추, 대파, 목살, 다진 고추 장아찌, 설탕, 스테이크 소스, 올리고당
A27: =recipe!C27 -> 엠티 오후의 라면 | B27: =IFERROR(__xludf.DUMMYFUNCTION("TRIM( REGEXEXTRACT( raw!A27, ""(?s)●\s*재료(.*)●\s*조리 방법"" ) ) "),"라면, 밀가루, 쇠고기 스프, 오징어, 계란") -> 라면, 밀가루, 쇠고기 스프, 오징어, 계란
A28: =recipe!C28 -> 봉선아 시집가자미 | B28: =IFERROR(__xludf.DUMMYFUNCTION("TRIM( REGEXEXTRACT( raw!A28, ""(?s)●\s*재료(.*)●\s*조리 방법"" ) ) "),"가자미, 양송이 버섯, 복분자 엑기스, 대파, 소금, 후추, 밀가루, 화이트 와인, 버터") -> 가자미, 양송이 버섯, 복분자 엑기스, 대파, 소금, 후추, 밀가루, 화이트 와인, 버터
A29: =recipe!C29 -> 스키니 신 | B29: =IFERROR(__xludf.DUMMYFUNCTION("TRIM( REGEXEXTRACT( raw!A29, ""(?s)●\s*재료(.*)●\s*조리 방법"" ) ) "),"키조개 관자, 단감, 양상추, 양파, 고구마, 감자, 올리브유") -> 키조개 관자, 단감, 양상추, 양파, 고구마, 감자, 올리브유
A30: =recipe!C30 -> 파티비프 | B30: =IFERROR(__xludf.DUMMYFUNCTION("TRIM( REGEXEXTRACT( raw!A30, ""(?s)●\s*재료(.*)●\s*조리 방법"" ) ) "),"밥, 등심, 느타리 버섯, 양송이 버섯, 양상추, 양파, 총각김치, 쌈장, 생크림") -> 밥, 등심, 느타리 버섯, 양송이 버섯, 양상추, 양파, 총각김치, 쌈장, 생크림
A31: =recipe!C31 -> 아이러브유부 | B31: =IFERROR(__xludf.DUMMYFUNCTION("TRIM( REGEXEXTRACT( raw!A31, ""(?s)●\s*재료(.*)●\s*조리 방법"" ) ) "),"삼겹살, 생크림, 달걀, 통마늘, 잣, 양파, 두반장, 굴소스, 고추장아찌 국물, 핫소스") -> 삼겹살, 생크림, 달걀, 통마늘, 잣, 양파, 두반장, 굴소스, 고추장아찌 국물, 핫소스
A32: =recipe!C32 -> 곤약 봉골레 곤봉 | B32: =IFERROR(__xludf.DUMMYFUNCTION("TRIM( REGEXEXTRACT( raw!A32, ""(?s)●\s*재료(.*)●\s*조리 방법"" ) ) "),"곤약, 파프리카, 바지락, 올리브 오일, 마늘, 소금, 후추") -> 곤약, 파프리카, 바지락, 올리브 오일, 마늘, 소금, 후추
A33: =recipe!C33 -> 렛잇컵 | B33: =IFERROR(__xludf.DUMMYFUNCTION("TRIM( REGEXEXTRACT( raw!A33, ""(?s)●\s*재료(.*)●\s*조리 방법"" ) ) "),"찐고구마, 두유, 딸기, 키위, 사과, 홍시, 플레인 요거트, 생고구마") -> 찐고구마, 두유, 딸기, 키위, 사과, 홍시, 플레인 요거트, 생고구마
A34: =recipe!C34 -> 마이 러블리 튀밥 | B34: =IFERROR(__xludf.DUMMYFUNCTION("TRIM( REGEXEXTRACT( raw!A34, ""(?s)●\s*재료(.*)●\s*조리 방법"" ) ) "),"파프리카, 버섯, 양파, 명란젓, 대파, 즉석밥, 참기름, 치즈, 소금, 후추, 올리브유, 마늘, 블랙올리브, 홍고추, 방울토마토, 토마토소스, 밀가루, 달걀, 빵가루, 식용유, 파슬리") -> 파프리카, 버섯, 양파, 명란젓, 대파, 즉석밥, 참기름, 치즈, 소금, 후추, 올리브유, 마늘, 블랙올리브, 홍고추, 방울토마토, 토마토소스, 밀가루, 달걀, 빵가루, 식용유, 파슬리
A35: =recipe!C35 -> 자투리타타 | B35: =IFERROR(__xludf.DUMMYFUNCTION("TRIM( REGEXEXTRACT( raw!A35, ""(?s)●\s*재료(.*)●\s*조리 방법"" ) ) "),"파프리카, 양파, 버섯, 명란젓, 달걀, 올리브유, 방울토마토, 마늘, 팽이버섯, 베이컨") -> 파프리카, 양파, 버섯, 명란젓, 달걀, 올리브유, 방울토마토, 마늘, 팽이버섯, 베이컨
A36: =recipe!C36 -> 괜찮아, 목심이야 | B36: =IFERROR(__xludf.DUMMYFUNCTION("TRIM( REGEXEXTRACT( raw!A36, ""(?s)●\s*재료(.*)●\s*조리 방법"" ) ) "),"돼지고기 목심, 양파, 당근, 양상추, 사과, 전분, 소금, 후추, 오리엔탈 소스, 식초, 설탕") -> 돼지고기 목심, 양파, 당근, 양상추, 사과, 전분, 소금, 후추, 오리엔탈 소스, 식초, 설탕
A37: =recipe!C37 -> 마이 스위트 베이비 | B37: =IFERROR(__xludf.DUMMYFUNCTION("TRIM( REGEXEXTRACT( raw!A37, ""(?s)●\s*재료(.*)●\s*조리 방법"" ) ) "),"소고기 등심, 사과, 레드와인, 흑설탕, 소금, 후추") -> 소고기 등심, 사과, 레드와인, 흑설탕, 소금, 후추
A38: =recipe!C38 -> 어란대첩 | B38: =IFERROR(__xludf.DUMMYFUNCTION("TRIM( REGEXEXTRACT( raw!A38, ""(?s)●\s*재료(.*)●\s*조리 방법"" ) ) "),"파스타면(엔젤헤어), 무, 어란, 올리브유, 쯔유, 소금, 후추") -> 파스타면(엔젤헤어), 무, 어란, 올리브유, 쯔유, 소금, 후추
A39: =recipe!C39 -> 뉴타운 달팽이 | B39: =IFERROR(__xludf.DUMMYFUNCTION("TRIM( REGEXEXTRACT( raw!A39, ""(?s)●\s*재료(.*)●\s*조리 방법"" ) ) "),"달팽이, 양파, 버터, 매시드 포테이토 분말, 레드와인, 시금치") -> 달팽이, 양파, 버터, 매시드 포테이토 분말, 레드와인, 시금치
A40: =recipe!C40 -> 삼국회담 | B40: =IFERROR(__xludf.DUMMYFUNCTION("TRIM( REGEXEXTRACT( raw!A40, ""(?s)●\s*재료(.*)●\s*조리 방법"" ) ) "),"양갈비, 쌀국수면, 커민, 마늘, 중국 고추소스, 코코넛 밀크, 새우젓, 말린 양파, 피쉬소스, 동치미 국물, 탄산수, 참기름") -> 양갈비, 쌀국수면, 커민, 마늘, 중국 고추소스, 코코넛 밀크, 새우젓, 말린 양파, 피쉬소스, 동치미 국물, 탄산수, 참기름
...

Sheet recipe
A1: full_title_raw | B1: chef_name | C1: recipe_title | D1: category
A2: =IFERROR(__xludf.DUMMYFUNCTION("REGEXEXTRACT(raw!A2, ""<\s*(.+?)\s*>"") "),"정창욱 셰프 - 치킨 밀푀유") -> 정창욱 셰프 - 치킨 밀푀유 | B2: =IFERROR(__xludf.DUMMYFUNCTION("TRIM( SUBSTITUTE( INDEX(SPLIT($A2,""-""),1), ""셰프"", """" ) ) "),"정창욱") -> 정창욱 | C2: =IFERROR(__xludf.DUMMYFUNCTION("TRIM(INDEX(SPLIT($A2,""-""),2)) "),"치킨 밀푀유") -> 치킨 밀푀유
A3: =IFERROR(__xludf.DUMMYFUNCTION("REGEXEXTRACT(raw!A3, ""<\s*(.+?)\s*>"") "),"홍석천 셰프 - 취닭거리") -> 홍석천 셰프 - 취닭거리 | B3: =IFERROR(__xludf.DUMMYFUNCTION("TRIM( SUBSTITUTE( INDEX(SPLIT($A3,""-""),1), ""셰프"", """" ) ) "),"홍석천") -> 홍석천 | C3: =IFERROR(__xludf.DUMMYFUNCTION("TRIM(INDEX(SPLIT($A3,""-""),2)) "),"취닭거리") -> 취닭거리
A4: =IFERROR(__xludf.DUMMYFUNCTION("REGEXEXTRACT(raw!A4, ""<\s*(.+?)\s*>"") "),"최현석 - 닭딸") -> 최현석 - 닭딸 | B4: =IFERROR(__xludf.DUMMYFUNCTION("TRIM( SUBSTITUTE( INDEX(SPLIT($A4,""-""),1), ""셰프"", """" ) ) "),"최현석") -> 최현석 | C4: =IFERROR(__xludf.DUMMYFUNCTION("TRIM(INDEX(SPLIT($A4,""-""),2)) "),"닭딸") -> 닭딸
A5: =IFERROR(__xludf.DUMMYFUNCTION("REGEXEXTRACT(raw!A5, ""<\s*(.+?)\s*>"") "),"김풍 셰프 - 어머니 맛 풍족밥") -> 김풍 셰프 - 어머니 맛 풍족밥 | B5: =IFERROR(__xludf.DUMMYFUNCTION("TRIM( SUBSTITUTE( INDEX(SPLIT($A5,""-""),1), ""셰프"", """" ) ) "),"김풍") -> 김풍 | C5: =IFERROR(__xludf.DUMMYFUNCTION("TRIM(INDEX(SPLIT($A5,""-""),2)) "),"어머니 맛 풍족밥") -> 어머니 맛 풍족밥
A6: =IFERROR(__xludf.DUMMYFUNCTION("REGEXEXTRACT(raw!A6, ""<\s*(.+?)\s*>"") "),"샘킴 셰프 - 치킨 요로케") -> 샘킴 셰프 - 치킨 요로케 | B6: =IFERROR(__xludf.DUMMYFUNCTION("TRIM( SUBSTITUTE( INDEX(SPLIT($A6,""-""),1), ""셰프"", """" ) ) "),"샘킴") -> 샘킴 | C6: =IFERROR(__xludf.DUMMYFUNCTION("TRIM(INDEX(SPLIT($A6,""-""),2)) "),"치킨 요로케") -> 치킨 요로케
A7: =IFERROR(__xludf.DUMMYFUNCTION("REGEXEXTRACT(raw!A7, ""<\s*(.+?)\s*>"") "),"미카엘 셰프 - 포크 미트볼") -> 미카엘 셰프 - 포크 미트볼 | B7: =IFERROR(__xludf.DUMMYFUNCTION("TRIM( SUBSTITUTE( INDEX(SPLIT($A7,""-""),1), ""셰프"", """" ) ) "),"미카엘") -> 미카엘 | C7: =IFERROR(__xludf.DUMMYFUNCTION("TRIM(INDEX(SPLIT($A7,""-""),2)) "),"포크 미트볼") -> 포크 미트볼
A8: =IFERROR(__xludf.DUMMYFUNCTION("REGEXEXTRACT(raw!A8, ""<\s*(.+?)\s*>"") "),"홍석천 셰프 - 만두부인 육수터졌네") -> 홍석천 셰프 - 만두부인 육수터졌네 | B8: =IFERROR(__xludf.DUMMYFUNCTION("TRIM( SUBSTITUTE( INDEX(SPLIT($A8,""-""),1), ""셰프"", """" ) ) "),"홍석천") -> 홍석천 | C8: =IFERROR(__xludf.DUMMYFUNCTION("TRIM(INDEX(SPLIT($A8,""-""),2)) "),"만두부인 육수터졌네") -> 만두부인 육수터졌네
A9: =IFERROR(__xludf.DUMMYFUNCTION("REGEXEXTRACT(raw!A9, ""<\s*(.+?)\s*>"") "),"정창욱 셰프 - 심쿵 오믈렛") -> 정창욱 셰프 - 심쿵 오믈렛 | B9: =IFERROR(__xludf.DUMMYFUNCTION("TRIM( SUBSTITUTE( INDEX(SPLIT($A9,""-""),1), ""셰프"", """" ) ) "),"정창욱") -> 정창욱 | C9: =IFERROR(__xludf.DUMMYFUNCTION("TRIM(INDEX(SPLIT($A9,""-""),2)) "),"심쿵 오믈렛") -> 심쿵 오믈렛
A10: =IFERROR(__xludf.DUMMYFUNCTION("REGEXEXTRACT(raw!A10, ""<\s*(.+?)\s*>"") "),"샘킴 셰프 - 엔초비 파스타") -> 샘킴 셰프 - 엔초비 파스타 | B10: =IFERROR(__xludf.DUMMYFUNCTION("TRIM( SUBSTITUTE( INDEX(SPLIT($A10,""-""),1), ""셰프"", """" ) ) "),"샘킴") -> 샘킴 | C10: =IFERROR(__xludf.DUMMYFUNCTION("TRIM(INDEX(SPLIT($A10,""-""),2)) "),"엔초비 파스타") -> 엔초비 파스타
A11: =IFERROR(__xludf.DUMMYFUNCTION("REGEXEXTRACT(raw!A11, ""<\s*(.+?)\s*>"") "),"김풍 셰프 - 고기와 썸타는 떡국떡 삼합") -> 김풍 셰프 - 고기와 썸타는 떡국떡 삼합 | B11: =IFERROR(__xludf.DUMMYFUNCTION("TRIM( SUBSTITUTE( INDEX(SPLIT($A11,""-""),1), ""셰프"", """" ) ) "),"김풍") -> 김풍 | C11: =IFERROR(__xludf.DUMMYFUNCTION("TRIM(INDEX(SPLIT($A11,""-""),2)) "),"고기와 썸타는 떡국떡 삼합") -> 고기와 썸타는 떡국떡 삼합
A12: =IFERROR(__xludf.DUMMYFUNCTION("REGEXEXTRACT(raw!A12, ""<\s*(.+?)\s*>"") "),"최현석 셰프 - 와닭") -> 최현석 셰프 - 와닭 | B12: =IFERROR(__xludf.DUMMYFUNCTION("TRIM( SUBSTITUTE( INDEX(SPLIT($A12,""-""),1), ""셰프"", """" ) ) "),"최현석") -> 최현석 | C12: =IFERROR(__xludf.DUMMYFUNCTION("TRIM(INDEX(SPLIT($A12,""-""),2)) "),"와닭") -> 와닭
A13: =IFERROR(__xludf.DUMMYFUNCTION("REGEXEXTRACT(raw!A13, ""<\s*(.+?)\s*>"") "),"미카엘 셰프 - 브로콜리 치킨") -> 미카엘 셰프 - 브로콜리 치킨 | B13: =IFERROR(__xludf.DUMMYFUNCTION("TRIM( SUBSTITUTE( INDEX(SPLIT($A13,""-""),1), ""셰프"", """" ) ) "),"미카엘") -> 미카엘 | C13: =IFERROR(__xludf.DUMMYFUNCTION("TRIM(INDEX(SPLIT($A13,""-""),2)) "),"브로콜리 치킨") -> 브로콜리 치킨
A14: =IFERROR(__xludf.DUMMYFUNCTION("REGEXEXTRACT(raw!A14, ""<\s*(.+?)\s*>"") "),"정창욱 셰프 - 삼겹살 플레이트") -> 정창욱 셰프 - 삼겹살 플레이트 | B14: =IFERROR(__xludf.DUMMYFUNCTION("TRIM( SUBSTITUTE( INDEX(SPLIT($A14,""-""),1), ""셰프"", """" ) ) "),"정창욱") -> 정창욱 | C14: =IFERROR(__xludf.DUMMYFUNCTION("TRIM(INDEX(SPLIT($A14,""-""),2)) "),"삼겹살 플레이트") -> 삼겹살 플레이트
A15: =IFERROR(__xludf.DUMMYFUNCTION("REGEXEXTRACT(raw!A15, ""<\s*(.+?)\s*>"") "),"최현석 셰프 - 강남비빔면") -> 최현석 셰프 - 강남비빔면 | B15: =IFERROR(__xludf.DUMMYFUNCTION("TRIM( SUBSTITUTE( INDEX(SPLIT($A15,""-""),1), ""셰프"", """" ) ) "),"최현석") -> 최현석 | C15: =IFERROR(__xludf.DUMMYFUNCTION("TRIM(INDEX(SPLIT($A15,""-""),2)) "),"강남비빔면") -> 강남비빔면
A16: =IFERROR(__xludf.DUMMYFUNCTION("REGEXEXTRACT(raw!A16, ""<\s*(.+?)\s*>"") "),"샘킴 셰프 - 나 또 브리또") -> 샘킴 셰프 - 나 또 브리또 | B16: =IFERROR(__xludf.DUMMYFUNCTION("TRIM( SUBSTITUTE( INDEX(SPLIT($A16,""-""),1), ""셰프"", """" ) ) "),"샘킴") -> 샘킴 | C16: =IFERROR(__xludf.DUMMYFUNCTION("TRIM(INDEX(SPLIT($A16,""-""),2)) "),"나 또 브리또") -> 나 또 브리또
A17: =IFERROR(__xludf.DUMMYFUNCTION("REGEXEXTRACT(raw!A17, ""<\s*(.+?)\s*>"") "),"김풍 셰프 - 갸루상 케이크") -> 김풍 셰프 - 갸루상 케이크 | B17: =IFERROR(__xludf.DUMMYFUNCTION("TRIM( SUBSTITUTE( INDEX(SPLIT($A17,""-""),1), ""셰프"", """" ) ) "),"김풍") -> 김풍 | C17: =IFERROR(__xludf.DUMMYFUNCTION("TRIM(INDEX(SPLIT($A17,""-""),2)) "),"갸루상 케이크") -> 갸루상 케이크
A18: =IFERROR(__xludf.DUMMYFUNCTION("REGEXEXTRACT(raw!A18, ""<\s*(.+?)\s*>"") "),"미카엘 셰프 - PLETKA") -> 미카엘 셰프 - PLETKA | B18: =IFERROR(__xludf.DUMMYFUNCTION("TRIM( SUBSTITUTE( INDEX(SPLIT($A18,""-""),1), ""셰프"", """" ) ) "),"미카엘") -> 미카엘 | C18: =IFERROR(__xludf.DUMMYFUNCTION("TRIM(INDEX(SPLIT($A18,""-""),2)) "),"PLETKA") -> PLETKA
A19: =IFERROR(__xludf.DUMMYFUNCTION("REGEXEXTRACT(raw!A19, ""<\s*(.+?)\s*>"") "),"홍석천 셰프 - 다 줄게라면") -> 홍석천 셰프 - 다 줄게라면 | B19: =IFERROR(__xludf.DUMMYFUNCTION("TRIM( SUBSTITUTE( INDEX(SPLIT($A19,""-""),1), ""셰프"", """" ) ) "),"홍석천") -> 홍석천 | C19: =IFERROR(__xludf.DUMMYFUNCTION("TRIM(INDEX(SPLIT($A19,""-""),2)) "),"다 줄게라면") -> 다 줄게라면
A20: =IFERROR(__xludf.DUMMYFUNCTION("REGEXEXTRACT(raw!A20, ""<\s*(.+?)\s*>"") "),"정창욱 셰프 - 우리집에 오.새.요") -> 정창욱 셰프 - 우리집에 오.새.요 | B20: =IFERROR(__xludf.DUMMYFUNCTION("TRIM( SUBSTITUTE( INDEX(SPLIT($A20,""-""),1), ""셰프"", """" ) ) "),"정창욱") -> 정창욱 | C20: =IFERROR(__xludf.DUMMYFUNCTION("TRIM(INDEX(SPLIT($A20,""-""),2)) "),"우리집에 오.새.요") -> 우리집에 오.새.요
A21: =IFERROR(__xludf.DUMMYFUNCTION("REGEXEXTRACT(raw!A21, ""<\s*(.+?)\s*>"") "),"샘킴 셰프 - Mr.콩chu~♥") -> 샘킴 셰프 - Mr.콩chu~♥ | B21: =IFERROR(__xludf.DUMMYFUNCTION("TRIM( SUBSTITUTE( INDEX(SPLIT($A21,""-""),1), ""셰프"", """" ) ) "),"샘킴") -> 샘킴 | C21: =IFERROR(__xludf.DUMMYFUNCTION("TRIM(INDEX(SPLIT($A21,""-""),2)) "),"Mr.콩chu~♥") -> Mr.콩chu~♥
A22: =IFERROR(__xludf.DUMMYFUNCTION("REGEXEXTRACT(raw!A22, ""<\s*(.+?)\s*>"") "),"최현석 셰프 - For덕") -> 최현석 셰프 - For덕 | B22: =IFERROR(__xludf.DUMMYFUNCTION("TRIM( SUBSTITUTE( INDEX(SPLIT($A22,""-""),1), ""셰프"", """" ) ) "),"최현석") -> 최현석 | C22: =IFERROR(__xludf.DUMMYFUNCTION("TRIM(INDEX(SPLIT($A22,""-""),2)) "),"For덕") -> For덕
A23: =IFERROR(__xludf.DUMMYFUNCTION("REGEXEXTRACT(raw!A23, ""<\s*(.+?)\s*>"") "),"미카엘 셰프 - 프로틴 스틱") -> 미카엘 셰프 - 프로틴 스틱 | B23: =IFERROR(__xludf.DUMMYFUNCTION("TRIM( SUBSTITUTE( INDEX(SPLIT($A23,""-""),1), ""셰프"", """" ) ) "),"미카엘") -> 미카엘 | C23: =IFERROR(__xludf.DUMMYFUNCTION("TRIM(INDEX(SPLIT($A23,""-""),2)) "),"프로틴 스틱") -> 프로틴 스틱
A24: =IFERROR(__xludf.DUMMYFUNCTION("REGEXEXTRACT(raw!A24, ""<\s*(.+?)\s*>"") "),"홍석천 셰프 - 불닭 소시지") -> 홍석천 셰프 - 불닭 소시지 | B24: =IFERROR(__xludf.DUMMYFUNCTION("TRIM( SUBSTITUTE( INDEX(SPLIT($A24,""-""),1), ""셰프"", """" ) ) "),"홍석천") -> 홍석천 | C24: =IFERROR(__xludf.DUMMYFUNCTION("TRIM(INDEX(SPLIT($A24,""-""),2)) "),"불닭 소시지") -> 불닭 소시지
A25: =IFERROR(__xludf.DUMMYFUNCTION("REGEXEXTRACT(raw!A25, ""<\s*(.+?)\s*>"") "),"김풍 셰프 - 매우면 참치 & 쏘루아밀크") -> 김풍 셰프 - 매우면 참치 & 쏘루아밀크 | B25: =IFERROR(__xludf.DUMMYFUNCTION("TRIM( SUBSTITUTE( INDEX(SPLIT($A25,""-""),1), ""셰프"", """" ) ) "),"김풍") -> 김풍 | C25: =IFERROR(__xludf.DUMMYFUNCTION("TRIM(INDEX(SPLIT($A25,""-""),2)) "),"매우면 참치 & 쏘루아밀크") -> 매우면 참치 & 쏘루아밀크
A26: =IFERROR(__xludf.DUMMYFUNCTION("REGEXEXTRACT(raw!A26, ""<\s*(.+?)\s*>"") "),"정창욱 셰프 - 삼층돈탑") -> 정창욱 셰프 - 삼층돈탑 | B26: =IFERROR(__xludf.DUMMYFUNCTION("TRIM( SUBSTITUTE( INDEX(SPLIT($A26,""-""),1), ""셰프"", """" ) ) "),"정창욱") -> 정창욱 | C26: =IFERROR(__xludf.DUMMYFUNCTION("TRIM(INDEX(SPLIT($A26,""-""),2)) "),"삼층돈탑") -> 삼층돈탑
A27: =IFERROR(__xludf.DUMMYFUNCTION("REGEXEXTRACT(raw!A27, ""<\s*(.+?)\s*>"") "),"김풍 셰프 - 엠티 오후의 라면") -> 김풍 셰프 - 엠티 오후의 라면 | B27: =IFERROR(__xludf.DUMMYFUNCTION("TRIM( SUBSTITUTE( INDEX(SPLIT($A27,""-""),1), ""셰프"", """" ) ) "),"김풍") -> 김풍 | C27: =IFERROR(__xludf.DUMMYFUNCTION("TRIM(INDEX(SPLIT($A27,""-""),2)) "),"엠티 오후의 라면") -> 엠티 오후의 라면
A28: =IFERROR(__xludf.DUMMYFUNCTION("REGEXEXTRACT(raw!A28, ""<\s*(.+?)\s*>"") "),"최현석 셰프 - 봉선아 시집가자미") -> 최현석 셰프 - 봉선아 시집가자미 | B28: =IFERROR(__xludf.DUMMYFUNCTION("TRIM( SUBSTITUTE( INDEX(SPLIT($A28,""-""),1), ""셰프"", """" ) ) "),"최현석") -> 최현석 | C28: =IFERROR(__xludf.DUMMYFUNCTION("TRIM(INDEX(SPLIT($A28,""-""),2)) "),"봉선아 시집가자미") -> 봉선아 시집가자미
A29: =IFERROR(__xludf.DUMMYFUNCTION("REGEXEXTRACT(raw!A29, ""<\s*(.+?)\s*>"") "),"샘킴 - 스키니 신") -> 샘킴 - 스키니 신 | B29: =IFERROR(__xludf.DUMMYFUNCTION("TRIM( SUBSTITUTE( INDEX(SPLIT($A29,""-""),1), ""셰프"", """" ) ) "),"샘킴") -> 샘킴 | C29: =IFERROR(__xludf.DUMMYFUNCTION("TRIM(INDEX(SPLIT($A29,""-""),2)) "),"스키니 신") -> 스키니 신
A30: =IFERROR(__xludf.DUMMYFUNCTION("REGEXEXTRACT(raw!A30, ""<\s*(.+?)\s*>"") "),"미카엘 - 파티비프") -> 미카엘 - 파티비프 | B30: =IFERROR(__xludf.DUMMYFUNCTION("TRIM( SUBSTITUTE( INDEX(SPLIT($A30,""-""),1), ""셰프"", """" ) ) "),"미카엘") -> 미카엘 | C30: =IFERROR(__xludf.DUMMYFUNCTION("TRIM(INDEX(SPLIT($A30,""-""),2)) "),"파티비프") -> 파티비프
A31: =IFERROR(__xludf.DUMMYFUNCTION("REGEXEXTRACT(raw!A31, ""<\s*(.+?)\s*>"") "),"홍석천 - 아이러브유부") -> 홍석천 - 아이러브유부 | B31: =IFERROR(__xludf.DUMMYFUNCTION("TRIM( SUBSTITUTE( INDEX(SPLIT($A31,""-""),1), ""셰프"", """" ) ) "),"홍석천") -> 홍석천 | C31: =IFERROR(__xludf.DUMMYFUNCTION("TRIM(INDEX(SPLIT($A31,""-""),2)) "),"아이러브유부") -> 아이러브유부
A32: =IFERROR(__xludf.DUMMYFUNCTION("REGEXEXTRACT(raw!A32, ""<\s*(.+?)\s*>"") "),"최현석 셰프 - 곤약 봉골레 곤봉") -> 최현석 셰프 - 곤약 봉골레 곤봉 | B32: =IFERROR(__xludf.DUMMYFUNCTION("TRIM( SUBSTITUTE( INDEX(SPLIT($A32,""-""),1), ""셰프"", """" ) ) "),"최현석") -> 최현석 | C32: =IFERROR(__xludf.DUMMYFUNCTION("TRIM(INDEX(SPLIT($A32,""-""),2)) "),"곤약 봉골레 곤봉") -> 곤약 봉골레 곤봉
A33: =IFERROR(__xludf.DUMMYFUNCTION("REGEXEXTRACT(raw!A33, ""<\s*(.+?)\s*>"") "),"홍석천 셰프 - 렛잇컵") -> 홍석천 셰프 - 렛잇컵 | B33: =IFERROR(__xludf.DUMMYFUNCTION("TRIM( SUBSTITUTE( INDEX(SPLIT($A33,""-""),1), ""셰프"", """" ) ) "),"홍석천") -> 홍석천 | C33: =IFERROR(__xludf.DUMMYFUNCTION("TRIM(INDEX(SPLIT($A33,""-""),2)) "),"렛잇컵") -> 렛잇컵
A34: =IFERROR(__xludf.DUMMYFUNCTION("REGEXEXTRACT(raw!A34, ""<\s*(.+?)\s*>"") "),"샘킴 셰프 - 마이 러블리 튀밥") -> 샘킴 셰프 - 마이 러블리 튀밥 | B34: =IFERROR(__xludf.DUMMYFUNCTION("TRIM( SUBSTITUTE( INDEX(SPLIT($A34,""-""),1), ""셰프"", """" ) ) "),"샘킴") -> 샘킴 | C34: =IFERROR(__xludf.DUMMYFUNCTION("TRIM(INDEX(SPLIT($A34,""-""),2)) "),"마이 러블리 튀밥") -> 마이 러블리 튀밥
A35: =IFERROR(__xludf.DUMMYFUNCTION("REGEXEXTRACT(raw!A35, ""<\s*(.+?)\s*>"") "),"김풍 셰프 - 자투리타타") -> 김풍 셰프 - 자투리타타 | B35: =IFERROR(__xludf.DUMMYFUNCTION("TRIM( SUBSTITUTE( INDEX(SPLIT($A35,""-""),1), ""셰프"", """" ) ) "),"김풍") -> 김풍 | C35: =IFERROR(__xludf.DUMMYFUNCTION("TRIM(INDEX(SPLIT($A35,""-""),2)) "),"자투리타타") -> 자투리타타
A36: =IFERROR(__xludf.DUMMYFUNCTION("REGEXEXTRACT(raw!A36, ""<\s*(.+?)\s*>"") "),"정창욱 셰프 - 괜찮아, 목심이야") -> 정창욱 셰프 - 괜찮아, 목심이야 | B36: =IFERROR(__xludf.DUMMYFUNCTION("TRIM( SUBSTITUTE( INDEX(SPLIT($A36,""-""),1), ""셰프"", """" ) ) "),"정창욱") -> 정창욱 | C36: =IFERROR(__xludf.DUMMYFUNCTION("TRIM(INDEX(SPLIT($A36,""-""),2)) "),"괜찮아, 목심이야") -> 괜찮아, 목심이야
A37: =IFERROR(__xludf.DUMMYFUNCTION("REGEXEXTRACT(raw!A37, ""<\s*(.+?)\s*>"") "),"미카엘 셰프 - 마이 스위트 베이비") -> 미카엘 셰프 - 마이 스위트 베이비 | B37: =IFERROR(__xludf.DUMMYFUNCTION("TRIM( SUBSTITUTE( INDEX(SPLIT($A37,""-""),1), ""셰프"", """" ) ) "),"미카엘") -> 미카엘 | C37: =IFERROR(__xludf.DUMMYFUNCTION("TRIM(INDEX(SPLIT($A37,""-""),2)) "),"마이 스위트 베이비") -> 마이 스위트 베이비
A38: =IFERROR(__xludf.DUMMYFUNCTION("REGEXEXTRACT(raw!A38, ""<\s*(.+?)\s*>"") "),"최현석 셰프 - 어란대첩") -> 최현석 셰프 - 어란대첩 | B38: =IFERROR(__xludf.DUMMYFUNCTION("TRIM( SUBSTITUTE( INDEX(SPLIT($A38,""-""),1), ""셰프"", """" ) ) "),"최현석") -> 최현석 | C38: =IFERROR(__xludf.DUMMYFUNCTION("TRIM(INDEX(SPLIT($A38,""-""),2)) "),"어란대첩") -> 어란대첩
A39: =IFERROR(__xludf.DUMMYFUNCTION("REGEXEXTRACT(raw!A39, ""<\s*(.+?)\s*>"") "),"박준우 셰프 - 뉴타운 달팽이") -> 박준우 셰프 - 뉴타운 달팽이 | B39: =IFERROR(__xludf.DUMMYFUNCTION("TRIM( SUBSTITUTE( INDEX(SPLIT($A39,""-""),1), ""셰프"", """" ) ) "),"박준우") -> 박준우 | C39: =IFERROR(__xludf.DUMMYFUNCTION("TRIM(INDEX(SPLIT($A39,""-""),2)) "),"뉴타운 달팽이") -> 뉴타운 달팽이
A40: =IFERROR(__xludf.DUMMYFUNCTION("REGEXEXTRACT(raw!A40, ""<\s*(.+?)\s*>"") "),"홍석천 셰프 - 삼국회담") -> 홍석천 셰프 - 삼국회담 | B40: =IFERROR(__xludf.DUMMYFUNCTION("TRIM( SUBSTITUTE( INDEX(SPLIT($A40,""-""),1), ""셰프"", """" ) ) "),"홍석천") -> 홍석천 | C40: =IFERROR(__xludf.DUMMYFUNCTION("TRIM(INDEX(SPLIT($A40,""-""),2)) "),"삼국회담") -> 삼국회담
...

Sheet step
A1: recipe_title | B1: step_text
A2: =recipe!C2 -> 치킨 밀푀유 | B2: =IFERROR(__xludf.DUMMYFUNCTION("TRIM( REGEXEXTRACT( raw!A2, ""(?s)●\s*조리 방법(.*)"" ) ) "),"1. 파프리카, 양배추, 슬라이스 햄을 썰어서 볶는다. 2. 닭가슴살에 소금, 후추를 뿌린 후 팬에 굽고, 잠시 식힌 후 얇게 포를 뜬다. 3. 포를 뜬 가슴살, 볶은 채소와 햄, 치즈, 토마토소스를 켜켜이 쌓는다. *동시에 작은 프라이팬에 크림과 가루치즈를 붓고 약불에 끓여 놓는다 4. 오븐에 5분간 굽고 홀그레인 머스터드, 크림소스, 구운 바게트를 곁들인다.") -> 1. 파프리카, 양배추, 슬라이스 햄을 썰어서 볶는다. 2. 닭가슴살에 소금, 후추를 뿌린 후 팬에 굽고, 잠시 식힌 후 얇게 포를 뜬다. 3. 포를 뜬 가슴살, 볶은 채소와 햄, 치즈, 토마토소스를 켜켜이 쌓는다. *동시에 작은 프라이팬에 크림과 가루치즈를 붓고 약불에 끓여 놓는다 4. 오븐에 5분간 굽고 홀그레인 머스터드, 크림소스, 구운 바게트를 곁들인다.
A3: =recipe!C3 -> 취닭거리 | B3: =IFERROR(__xludf.DUMMYFUNCTION("TRIM( REGEXEXTRACT( raw!A3, ""(?s)●\s*조리 방법(.*)"" ) ) "),"1. 살을 발라낸 족발에 버터, 라조장을 넣고 볶는다. 2. 취두부를 팬에서 익힌다. 3. 해동한 닭죽과 볶은 족발, 취두부를 함께 곁들인다.") -> 1. 살을 발라낸 족발에 버터, 라조장을 넣고 볶는다. 2. 취두부를 팬에서 익힌다. 3. 해동한 닭죽과 볶은 족발, 취두부를 함께 곁들인다.
A4: =recipe!C4 -> 닭딸 | B4: =IFERROR(__xludf.DUMMYFUNCTION("TRIM( REGEXEXTRACT( raw!A4, ""(?s)●\s*조리 방법(.*)"" ) ) "),"1. 복분자를 가열하다가 우유와 레몬즙을 넣고 졸인다. 2. 바케트는 썰어서 팬에 굽는다. 3. 소금 후추로 간을 한 닭가슴살을 마늘과 함께 굽는다. 4. 구운 닭가슴살에 복분자 소스와 바게트를 함께 곁들인다.") -> 1. 복분자를 가열하다가 우유와 레몬즙을 넣고 졸인다. 2. 바케트는 썰어서 팬에 굽는다. 3. 소금 후추로 간을 한 닭가슴살을 마늘과 함께 굽는다. 4. 구운 닭가슴살에 복분자 소스와 바게트를 함께 곁들인다.
A5: =recipe!C5 -> 어머니 맛 풍족밥 | B5: =IFERROR(__xludf.DUMMYFUNCTION("TRIM( REGEXEXTRACT( raw!A5, ""(?s)●\s*조리 방법(.*)"" ) ) "),"1. 살을 발라낸 치킨, 족발에 두반장, 라조장, 유자청 을 넣고 볶는다. 2. 어느 정도 볶다가 밀가루(또는 녹말)를 물에 풀어 좀 더 볶아내면 완성. 3. 뜨거운 밥에 끼얹어 먹는다.") -> 1. 살을 발라낸 치킨, 족발에 두반장, 라조장, 유자청 을 넣고 볶는다. 2. 어느 정도 볶다가 밀가루(또는 녹말)를 물에 풀어 좀 더 볶아내면 완성. 3. 뜨거운 밥에 끼얹어 먹는다.
A6: =recipe!C6 -> 치킨 요로케 | B6: =IFERROR(__xludf.DUMMYFUNCTION("TRIM( REGEXEXTRACT( raw!A6, ""(?s)●\s*조리 방법(.*)"" ) ) "),"1. 얇게 저민 닭가슴살에 소금, 후추를 뿌리고 밀가루를 묻혀 굽는다. 2. 잘게 썰은 양파와 슬라이스 햄을 함께 볶는다. 3. 토마토 소스에 구운 닭가슴살, 파마산 치즈, 모짜렐라 치즈를 넣고 가열한다. 4. 마지막으로 올리브유를 뿌려준다.") -> 1. 얇게 저민 닭가슴살에 소금, 후추를 뿌리고 밀가루를 묻혀 굽는다. 2. 잘게 썰은 양파와 슬라이스 햄을 함께 볶는다. 3. 토마토 소스에 구운 닭가슴살, 파마산 치즈, 모짜렐라 치즈를 넣고 가열한다. 4. 마지막으로 올리브유를 뿌려준다.
A7: =recipe!C7 -> 포크 미트볼 | B7: =IFERROR(__xludf.DUMMYFUNCTION("TRIM( REGEXEXTRACT( raw!A7, ""(?s)●\s*조리 방법(.*)"" ) ) "),"1. 믹서에 갈은 김치와 달걀 물을 섞어서 스크램블을 만든다. 2. 갈은 통조림 햄을 넓게 편 후 1을 넣고 말아준다. 3. 겉에 달걀 물을 뭍이고 팬에서 익혀준다. 4. 접시에 밥과 함께 곁들여 낸다.") -> 1. 믹서에 갈은 김치와 달걀 물을 섞어서 스크램블을 만든다. 2. 갈은 통조림 햄을 넓게 편 후 1을 넣고 말아준다. 3. 겉에 달걀 물을 뭍이고 팬에서 익혀준다. 4. 접시에 밥과 함께 곁들여 낸다.
A8: =recipe!C8 -> 만두부인 육수터졌네 | B8: =IFERROR(__xludf.DUMMYFUNCTION("TRIM( REGEXEXTRACT( raw!A8, ""(?s)●\s*조리 방법(.*)"" ) ) "),"① 뜨거운 팬에 올리브 오일을 두르고 다진 마늘을 볶다가 냉동만두를 굽는다. ② 겉은 바삭하게 구운 다음 버터를 조금 넣고 사골육수를 넣어 졸인다. ③ 졸여지면 발사믹 소스와 고추냉이, 토마토를 함께 넣어 볶는다. ④ 접시에 만두, 토마토 순으로 올리고 프로슈토 햄과 그뤼에르 치즈를 위에 토핑한다.") -> ① 뜨거운 팬에 올리브 오일을 두르고 다진 마늘을 볶다가 냉동만두를 굽는다. ② 겉은 바삭하게 구운 다음 버터를 조금 넣고 사골육수를 넣어 졸인다. ③ 졸여지면 발사믹 소스와 고추냉이, 토마토를 함께 넣어 볶는다. ④ 접시에 만두, 토마토 순으로 올리고 프로슈토 햄과 그뤼에르 치즈를 위에 토핑한다.
A9: =recipe!C9 -> 심쿵 오믈렛 | B9: =IFERROR(__xludf.DUMMYFUNCTION("TRIM( REGEXEXTRACT( raw!A9, ""(?s)●\s*조리 방법(.*)"" ) ) "),"① 달걀을 풀어놓는다. ② 프라이팬에 오일을 두르고 소금 후추 간을 한 연어를 굽는다. ③ 양파잼과 다진 브로콜리를 넣고 함께 굽는다. ④ 버터를 두른 팬에 풀어놓은 계란을 넣어 반숙으로 익힌다. (* 스크램블 에그 만들 듯이 약간 저어주며 익힌다) ⑤ 반숙으로 익힌 오믈렛에 구운 연어와 야채를 넣고 반으로 접는다. ⑥ 접시에 올리고 케찹을 뿌린다.") -> ① 달걀을 풀어놓는다. ② 프라이팬에 오일을 두르고 소금 후추 간을 한 연어를 굽는다. ③ 양파잼과 다진 브로콜리를 넣고 함께 굽는다. ④ 버터를 두른 팬에 풀어놓은 계란을 넣어 반숙으로 익힌다. (* 스크램블 에그 만들 듯이 약간 저어주며 익힌다) ⑤ 반숙으로 익힌 오믈렛에 구운 연어와 야채를 넣고 반으로 접는다. ⑥ 접시에 올리고 케찹을 뿌린다.
A10: =recipe!C10 -> 엔초비 파스타 | B10: =IFERROR(__xludf.DUMMYFUNCTION("TRIM( REGEXEXTRACT( raw!A10, ""(?s)●\s*조리 방법(.*)"" ) ) "),"① 올리브 오일에 파슬리와 다진 마늘, 찢은 바게트 빵을 섞어 프라이팬에 굽는다. ② 끓는 물에 파스타면을 삶는다. ③ 프라이팬에 올리브 오일을 두르고 애호박, 엔초비, 페페로치노, 파슬리를 넣어 볶는다. ④ 익은 파스타면을 팬으로 옮겨 모든 재료를 함께 볶는다. (기호에 따라 버터를 조금 넣는다.)") -> ① 올리브 오일에 파슬리와 다진 마늘, 찢은 바게트 빵을 섞어 프라이팬에 굽는다. ② 끓는 물에 파스타면을 삶는다. ③ 프라이팬에 올리브 오일을 두르고 애호박, 엔초비, 페페로치노, 파슬리를 넣어 볶는다. ④ 익은 파스타면을 팬으로 옮겨 모든 재료를 함께 볶는다. (기호에 따라 버터를 조금 넣는다.)
A11: =recipe!C11 -> 고기와 썸타는 떡국떡 삼합 | B11: =IFERROR(__xludf.DUMMYFUNCTION("TRIM( REGEXEXTRACT( raw!A11, ""(?s)●\s*조리 방법(.*)"" ) ) "),"① 맥주와 삼겹살을 한 번에 넣고 삶는다. ② 들기름 두른 팬에 김치를 볶다가 방울토마토 간 것, 케찹, 고추장을 넣고 볶는다. ③ 기름 두른 팬에 떡국떡을 굽는다. ④ 접시에 적당한 크기로 자른 삼겹살과 김치, 구운 떡국떡을 담아낸다.") -> ① 맥주와 삼겹살을 한 번에 넣고 삶는다. ② 들기름 두른 팬에 김치를 볶다가 방울토마토 간 것, 케찹, 고추장을 넣고 볶는다. ③ 기름 두른 팬에 떡국떡을 굽는다. ④ 접시에 적당한 크기로 자른 삼겹살과 김치, 구운 떡국떡을 담아낸다.
A12: =recipe!C12 -> 와닭 | B12: =IFERROR(__xludf.DUMMYFUNCTION("TRIM( REGEXEXTRACT( raw!A12, ""(?s)●\s*조리 방법(.*)"" ) ) "),"① 생닭을 해체한다. (껍질과 뼈는 사용하지 않는다.) ② 양파를 채 썰고, 마늘을 편 썬다. ③ 팬에 오일을 두르고 해체한 닭을 굽는다. ④ 다른 팬에 마늘과 양파를 넣고 볶다가 아티초크를 넣어 함께 볶는다. ⑤ 닭을 굽던 팬에 토마토 소스와 야채들을 넣어 함께 볶는다. ⑥ 적포도의 씨를 발라 프라이팬에 볶다가 모든재료를 함께 볶고 사골육수를 조금 넣어 익힌다.") -> ① 생닭을 해체한다. (껍질과 뼈는 사용하지 않는다.) ② 양파를 채 썰고, 마늘을 편 썬다. ③ 팬에 오일을 두르고 해체한 닭을 굽는다. ④ 다른 팬에 마늘과 양파를 넣고 볶다가 아티초크를 넣어 함께 볶는다. ⑤ 닭을 굽던 팬에 토마토 소스와 야채들을 넣어 함께 볶는다. ⑥ 적포도의 씨를 발라 프라이팬에 볶다가 모든재료를 함께 볶고 사골육수를 조금 넣어 익힌다.
A13: =recipe!C13 -> 브로콜리 치킨 | B13: =IFERROR(__xludf.DUMMYFUNCTION("TRIM( REGEXEXTRACT( raw!A13, ""(?s)●\s*조리 방법(.*)"" ) ) "),"① 브로콜리를 잘라서 소금 넣은 물에 데친 후 다진다. ② 방울토마토를 반으로 자르고 파프리카를 채썬다. ③ 닭가슴살을 반으로 갈라 소금 후추 간을 한 후 데친 브로콜리와 치즈를 넣고 이쑤시개로 고정해 굽는다. ④ 같은 팬에 파프리카와 방울토마토를 넣어 함께 익힌다. ⑤ 버터를 조금 넣고 물을 약간 부어 뚜껑을 덮어 익힌다. ⑥ 고춧가루를 조금 뿌린다.") -> ① 브로콜리를 잘라서 소금 넣은 물에 데친 후 다진다. ② 방울토마토를 반으로 자르고 파프리카를 채썬다. ③ 닭가슴살을 반으로 갈라 소금 후추 간을 한 후 데친 브로콜리와 치즈를 넣고 이쑤시개로 고정해 굽는다. ④ 같은 팬에 파프리카와 방울토마토를 넣어 함께 익힌다. ⑤ 버터를 조금 넣고 물을 약간 부어 뚜껑을 덮어 익힌다. ⑥ 고춧가루를 조금 뿌린다.
A14: =recipe!C14 -> 삼겹살 플레이트 | B14: =IFERROR(__xludf.DUMMYFUNCTION("TRIM( REGEXEXTRACT( raw!A14, ""(?s)●\s*조리 방법(.*)"" ) ) "),"① 삼겹살을 썰어서 소금후추 간을 해서 굽는다. ② 다른 팬에 버터와 통마늘, 채 썬 양파를 넣어 볶다가 간장, 미림, 다진생강, 다진마늘, 커피가루를 넣어 끓인다. ③ 삼겹살에 청주를 넣어 끓이다가 건져 야채와 함께 섞는다 ④ 채 썬 알배추를 듬뿍 넣고 뚜껑을 덮어 숨을 죽인다. ⑤ 아이스크림 스쿱으로 밥을 담고 익은 고기와 채소를 얹어 낸다.") -> ① 삼겹살을 썰어서 소금후추 간을 해서 굽는다. ② 다른 팬에 버터와 통마늘, 채 썬 양파를 넣어 볶다가 간장, 미림, 다진생강, 다진마늘, 커피가루를 넣어 끓인다. ③ 삼겹살에 청주를 넣어 끓이다가 건져 야채와 함께 섞는다 ④ 채 썬 알배추를 듬뿍 넣고 뚜껑을 덮어 숨을 죽인다. ⑤ 아이스크림 스쿱으로 밥을 담고 익은 고기와 채소를 얹어 낸다.
A15: =recipe!C15 -> 강남비빔면 | B15: =IFERROR(__xludf.DUMMYFUNCTION("TRIM( REGEXEXTRACT( raw!A15, ""(?s)●\s*조리 방법(.*)"" ) ) "),"① 삼겹살을 잘게 썰어서 기름에 바삭하게 튀긴다 ② 고추장과 딸기잼, 참기름, 고추냉이를 섞는다 ③ 끓는 물에 칼국수면을 삶는다 (넘칠 때쯤 찬물을 한 번 넣어 쫄깃함을 더한다) ④ 물에 씻은 새우젓을 기름에 튀긴다 ⑤ 익은 면을 찬물에 씻고 소스와 버무려 접시에 담은 뒤 튀긴 삼겹살과 새우젓, 오렌지를 토핑한다.") -> ① 삼겹살을 잘게 썰어서 기름에 바삭하게 튀긴다 ② 고추장과 딸기잼, 참기름, 고추냉이를 섞는다 ③ 끓는 물에 칼국수면을 삶는다 (넘칠 때쯤 찬물을 한 번 넣어 쫄깃함을 더한다) ④ 물에 씻은 새우젓을 기름에 튀긴다 ⑤ 익은 면을 찬물에 씻고 소스와 버무려 접시에 담은 뒤 튀긴 삼겹살과 새우젓, 오렌지를 토핑한다.
A16: =recipe!C16 -> 나 또 브리또 | B16: =IFERROR(__xludf.DUMMYFUNCTION("TRIM( REGEXEXTRACT( raw!A16, ""(?s)●\s*조리 방법(.*)"" ) ) "),"① 간장, 미림, 다진마늘, 후추, 어슷 썬 대파, 타이칠리소스, 낫토를 섞은 것에 샤브샤브용 고기를 넣어 재운다. ② 냉동새우볶음밥에 낫토, 버터를 넣어 볶는다. ③ 플레인 요거트와 레몬즙을 섞어 사워크림을 만들고 낫토를 잘게 다져 넣는다. ④ 또띠아를 팬에 굽고 다른 팬에 고기를 익힌다. ⑤ 또띠아 위에 볶음밥과 고기, 크림과 어슷썬 파를 얹어 낸다.") -> ① 간장, 미림, 다진마늘, 후추, 어슷 썬 대파, 타이칠리소스, 낫토를 섞은 것에 샤브샤브용 고기를 넣어 재운다. ② 냉동새우볶음밥에 낫토, 버터를 넣어 볶는다. ③ 플레인 요거트와 레몬즙을 섞어 사워크림을 만들고 낫토를 잘게 다져 넣는다. ④ 또띠아를 팬에 굽고 다른 팬에 고기를 익힌다. ⑤ 또띠아 위에 볶음밥과 고기, 크림과 어슷썬 파를 얹어 낸다.
A17: =recipe!C17 -> 갸루상 케이크 | B17: =IFERROR(__xludf.DUMMYFUNCTION("TRIM( REGEXEXTRACT( raw!A17, ""(?s)●\s*조리 방법(.*)"" ) ) "),"① 달걀의 흰자와 노른자를 분리한다. ② 노른자 2개와 설탕, 우유, 바닐라 아이스크림, 밀가루를 넣어 섞고 커스터드 크림이 될 때까지 전자렌지에 3분 간격으로 돌린다. ③ 또띠아를 6등분 해 기름에 튀겨낸다. ④ 튀긴 또띠아 위에 커스터드 크림을 층층이 올리고 반으로 자른 딸기를 토핑한다.") -> ① 달걀의 흰자와 노른자를 분리한다. ② 노른자 2개와 설탕, 우유, 바닐라 아이스크림, 밀가루를 넣어 섞고 커스터드 크림이 될 때까지 전자렌지에 3분 간격으로 돌린다. ③ 또띠아를 6등분 해 기름에 튀겨낸다. ④ 튀긴 또띠아 위에 커스터드 크림을 층층이 올리고 반으로 자른 딸기를 토핑한다.
A18: =recipe!C18 -> PLETKA | B18: =IFERROR(__xludf.DUMMYFUNCTION("TRIM( REGEXEXTRACT( raw!A18, ""(?s)●\s*조리 방법(.*)"" ) ) "),"① 길게 썬 돼지고기 안심과 베이컨의 윗부분을 이쑤시개로 고정한 후 머리땋 듯 땋고 끝부분도 이쑤시개로 고정해 팬에 굽는다. ② 소주를 부어 잡내를 날린다. ③ 김치, 양파, 당근을 잘게 썰어 같은 팬에 넣고 볶다가 물을 붓고 뚜껑을 덮는다. ④ 접시에 고기를 올리고 밥과 김치를 쌓아서 낸 후 다진 부추로 토핑한다.") -> ① 길게 썬 돼지고기 안심과 베이컨의 윗부분을 이쑤시개로 고정한 후 머리땋 듯 땋고 끝부분도 이쑤시개로 고정해 팬에 굽는다. ② 소주를 부어 잡내를 날린다. ③ 김치, 양파, 당근을 잘게 썰어 같은 팬에 넣고 볶다가 물을 붓고 뚜껑을 덮는다. ④ 접시에 고기를 올리고 밥과 김치를 쌓아서 낸 후 다진 부추로 토핑한다.
A19: =recipe!C19 -> 다 줄게라면 | B19: =IFERROR(__xludf.DUMMYFUNCTION("TRIM( REGEXEXTRACT( raw!A19, ""(?s)●\s*조리 방법(.*)"" ) ) "),"① 복분자주에 재운 삼겹살을 길게 찢은 김치와 함께 말아 부추로 고정한 후 팬에 굽는다. ② 물과 어묵통조림과 매운미소소스, 큼직하게 썬 알배추를 넣고 끓인다. ③ 면을 넣어 끓인다. ④ 접시에 끓인 라면을 담고 김치말이 삼겹살을 얹어서 낸다.") -> ① 복분자주에 재운 삼겹살을 길게 찢은 김치와 함께 말아 부추로 고정한 후 팬에 굽는다. ② 물과 어묵통조림과 매운미소소스, 큼직하게 썬 알배추를 넣고 끓인다. ③ 면을 넣어 끓인다. ④ 접시에 끓인 라면을 담고 김치말이 삼겹살을 얹어서 낸다.
A20: =recipe!C20 -> 우리집에 오.새.요 | B20: =IFERROR(__xludf.DUMMYFUNCTION("TRIM( REGEXEXTRACT( raw!A20, ""(?s)●\s*조리 방법(.*)"" ) ) "),"1. 청주, 미림, 양조간장, 국수장국을 끓여 소스를 만든다. 2. 오징어는 간장, 다진 마늘, 청주, 미림에 담가 간을 한다. 3. 채썬 채소와 칵테일 새우, 박력분, 전분, 얼음을 넣어 반죽을 한다. (* 반죽 후 얼음은 꼭 제거한다.) 4. 달궈진 기름에 반죽을 한국자씩 넣고 튀긴다. 5. 간을 한 오징어에 전분을 묻혀 튀긴다. 6. 그릇에 밥과 어슷썬 대파, 완성된 튀김과 갈은 무, 소스를 올려낸다.") -> 1. 청주, 미림, 양조간장, 국수장국을 끓여 소스를 만든다. 2. 오징어는 간장, 다진 마늘, 청주, 미림에 담가 간을 한다. 3. 채썬 채소와 칵테일 새우, 박력분, 전분, 얼음을 넣어 반죽을 한다. (* 반죽 후 얼음은 꼭 제거한다.) 4. 달궈진 기름에 반죽을 한국자씩 넣고 튀긴다. 5. 간을 한 오징어에 전분을 묻혀 튀긴다. 6. 그릇에 밥과 어슷썬 대파, 완성된 튀김과 갈은 무, 소스를 올려낸다.
A21: =recipe!C21 -> Mr.콩chu~♥ | B21: =IFERROR(__xludf.DUMMYFUNCTION("TRIM( REGEXEXTRACT( raw!A21, ""(?s)●\s*조리 방법(.*)"" ) ) "),"1. 두부의 물기를 제거한다. 2. 버터를 녹이고 밀가루, 두유를 넣어 소스를 만든다. 3. 계피맛 쿠키를 믹서에 갈고 설탕을 섞어둔다 4. 깍뚝 썬 두부에 전분을 묻혀 튀긴다. 5. 튀긴 두부에 계피설탕가루를 입힌다. 6. 그릇에 두유소스와 두부츄러스, 바닐라 아이스크림, 다진 초콜릿을 토핑한다.") -> 1. 두부의 물기를 제거한다. 2. 버터를 녹이고 밀가루, 두유를 넣어 소스를 만든다. 3. 계피맛 쿠키를 믹서에 갈고 설탕을 섞어둔다 4. 깍뚝 썬 두부에 전분을 묻혀 튀긴다. 5. 튀긴 두부에 계피설탕가루를 입힌다. 6. 그릇에 두유소스와 두부츄러스, 바닐라 아이스크림, 다진 초콜릿을 토핑한다.
A22: =recipe!C22 -> For덕 | B22: =IFERROR(__xludf.DUMMYFUNCTION("TRIM( REGEXEXTRACT( raw!A22, ""(?s)●\s*조리 방법(.*)"" ) ) "),"① 가지를 길게 썰어 올리브유를 두른 팬에 양면을 굽는다. ② 토마토는 열십자로 칼집을 내어 끓는 물에 데쳐 껍질을 벗긴다. ③ 적당한 크기로 썬 토마토와 다진 파프리카, 양파, 사과, 고추장아찌를 냄비에 넣고 으깨 소스를 만든다. ④ 토마토 소스를 넣어 풍미를 더한다. ⑤ 익은 가지를 격자 모양으로 놓고 소금 후추를 뿌린 후, 가운데 계란흰자 통조림을 넣어 감싼다. (* 비닐을 이용하면 좀 더 쉽게 모양을 잡을 수 있다.) ⑥ 모양이 잡힌 "&"가지를 올리브유를 두른 팬에 한 번 더 익힌다. ⑦ 접시에 소스와 가지를 담아 낸다.") -> ① 가지를 길게 썰어 올리브유를 두른 팬에 양면을 굽는다. ② 토마토는 열십자로 칼집을 내어 끓는 물에 데쳐 껍질을 벗긴다. ③ 적당한 크기로 썬 토마토와 다진 파프리카, 양파, 사과, 고추장아찌를 냄비에 넣고 으깨 소스를 만든다. ④ 토마토 소스를 넣어 풍미를 더한다. ⑤ 익은 가지를 격자 모양으로 놓고 소금 후추를 뿌린 후, 가운데 계란흰자 통조림을 넣어 감싼다. (* 비닐을 이용하면 좀 더 쉽게 모양을 잡을 수 있다.) ⑥ 모양이 잡힌 가지를 올리브유를 두른 팬에 한 번 더 익힌다. ⑦ 접시에 소스와 가지를 담아 낸다.
A23: =recipe!C23 -> 프로틴 스틱 | B23: =IFERROR(__xludf.DUMMYFUNCTION("TRIM( REGEXEXTRACT( raw!A23, ""(?s)●\s*조리 방법(.*)"" ) ) "),"① 계란 흰자 통조림과 닭가슴살, 파프리카, 양파를 깍둑썰기 해 꼬치에 끼운다. ② 꼬치에 소금, 후추를 두르고 그릴팬에 굽는다. ③ 당근, 사과를 강판에 채썰고, 식초, 올리브유, 다진 견과류를 뿌린다. ④ 접시에 샐러드를 깔고 꼬치를 위에 낸다.") -> ① 계란 흰자 통조림과 닭가슴살, 파프리카, 양파를 깍둑썰기 해 꼬치에 끼운다. ② 꼬치에 소금, 후추를 두르고 그릴팬에 굽는다. ③ 당근, 사과를 강판에 채썰고, 식초, 올리브유, 다진 견과류를 뿌린다. ④ 접시에 샐러드를 깔고 꼬치를 위에 낸다.
A24: =recipe!C24 -> 불닭 소시지 | B24: =IFERROR(__xludf.DUMMYFUNCTION("TRIM( REGEXEXTRACT( raw!A24, ""(?s)●\s*조리 방법(.*)"" ) ) "),"① 소시지를 끓는 물에 데쳐 기름기를 제거하고 적당한 크기로 썬다. ② 당면라면의 면을 끓는 물에 데쳐 찬물에 헹군 후, 매운라면 소스, 다진 청양고추에 버무린다. ③ 꼬치에 소시지를 꽂고, 양념한 면을 감는다. ④ 접시에 꼬치를 놓고 상추를 곁들여 낸다.") -> ① 소시지를 끓는 물에 데쳐 기름기를 제거하고 적당한 크기로 썬다. ② 당면라면의 면을 끓는 물에 데쳐 찬물에 헹군 후, 매운라면 소스, 다진 청양고추에 버무린다. ③ 꼬치에 소시지를 꽂고, 양념한 면을 감는다. ④ 접시에 꼬치를 놓고 상추를 곁들여 낸다.
A25: =recipe!C25 -> 매우면 참치 & 쏘루아밀크 | B25: =IFERROR(__xludf.DUMMYFUNCTION("TRIM( REGEXEXTRACT( raw!A25, ""(?s)●\s*조리 방법(.*)"" ) ) "),"① 식빵을 토스트기에 굽는다. ② 버터를 두른 팬에 기름 뺀 참치와 믹서에 간 토마토, 고춧가루를 넣고 끓인다. ③ 얼음을 담은 잔에 소주, 설탕, 인스턴트 커피 섞은 것을 넣고, 흰우유를 넣어 층을 낸다. ④ 구운 식빵을 적당한 크기로 자르고 참치 양념을 얹어낸다.") -> ① 식빵을 토스트기에 굽는다. ② 버터를 두른 팬에 기름 뺀 참치와 믹서에 간 토마토, 고춧가루를 넣고 끓인다. ③ 얼음을 담은 잔에 소주, 설탕, 인스턴트 커피 섞은 것을 넣고, 흰우유를 넣어 층을 낸다. ④ 구운 식빵을 적당한 크기로 자르고 참치 양념을 얹어낸다.
A26: =recipe!C26 -> 삼층돈탑 | B26: =IFERROR(__xludf.DUMMYFUNCTION("TRIM( REGEXEXTRACT( raw!A26, ""(?s)●\s*조리 방법(.*)"" ) ) "),"1. 알배추는 먹기 좋은 크기로 썰어둔다. 2. 대파는 채썰고, 마늘은 편으로 썰어둔다. 돼지고기는 먹기 좋은 크기로 자른다. 3. 전자레인지용 그릇에 알배추 - 채 썬 대파 - 돼지고기를 층층이 쌓고 소금 후추 간을 한다. 4. 랩을 두르고 3분 간격으로 렌지에 돌린다. 5. 다진 고추 장아찌와 국물, 설탕을 두른 소스와 스테이크소스, 올리고당을 섞은 소스를 함께 낸다.") -> 1. 알배추는 먹기 좋은 크기로 썰어둔다. 2. 대파는 채썰고, 마늘은 편으로 썰어둔다. 돼지고기는 먹기 좋은 크기로 자른다. 3. 전자레인지용 그릇에 알배추 - 채 썬 대파 - 돼지고기를 층층이 쌓고 소금 후추 간을 한다. 4. 랩을 두르고 3분 간격으로 렌지에 돌린다. 5. 다진 고추 장아찌와 국물, 설탕을 두른 소스와 스테이크소스, 올리고당을 섞은 소스를 함께 낸다.
A27: =recipe!C27 -> 엠티 오후의 라면 | B27: =IFERROR(__xludf.DUMMYFUNCTION("TRIM( REGEXEXTRACT( raw!A27, ""(?s)●\s*조리 방법(.*)"" ) ) "),"1. 끓는 물에 밀가루와 쇠고기 스프, 라면스프를 넣고 끓인다. 2. 채 썬 오징어와 면, 건더기 스프를 넣고 끓인다. 3. 계란 푼 것을 라면에 두른다. 4. 총각김치를 곁들여 낸다.") -> 1. 끓는 물에 밀가루와 쇠고기 스프, 라면스프를 넣고 끓인다. 2. 채 썬 오징어와 면, 건더기 스프를 넣고 끓인다. 3. 계란 푼 것을 라면에 두른다. 4. 총각김치를 곁들여 낸다.
A28: =recipe!C28 -> 봉선아 시집가자미 | B28: =IFERROR(__xludf.DUMMYFUNCTION("TRIM( REGEXEXTRACT( raw!A28, ""(?s)●\s*조리 방법(.*)"" ) ) "),"1. 팬 하나에 대파를 잘게 썰어 볶고, 다른 팬에는 양송이 버섯에 소금 후추 간을 해 볶는다. 2. 가자미는 껍질을 벗기고 뼈를 발라낸다. 3. 가자미에 소금 후추 간을 하고 밀가루를 뭍혀 올리브유를 두른 팬에 굽는다. 4. 가자미를 굽는 팬에 화이트와인과 복분자 엑기스를 부어 졸인다. 5. 그릇에 볶은 대파와 버섯을 놓고 그 위에 구운 가자미를 올린다. 6. 가자미 육즙이 남은 팬에 버터를 넣어 소스를 만든다.") -> 1. 팬 하나에 대파를 잘게 썰어 볶고, 다른 팬에는 양송이 버섯에 소금 후추 간을 해 볶는다. 2. 가자미는 껍질을 벗기고 뼈를 발라낸다. 3. 가자미에 소금 후추 간을 하고 밀가루를 뭍혀 올리브유를 두른 팬에 굽는다. 4. 가자미를 굽는 팬에 화이트와인과 복분자 엑기스를 부어 졸인다. 5. 그릇에 볶은 대파와 버섯을 놓고 그 위에 구운 가자미를 올린다. 6. 가자미 육즙이 남은 팬에 버터를 넣어 소스를 만든다.
A29: =recipe!C29 -> 스키니 신 | B29: =IFERROR(__xludf.DUMMYFUNCTION("TRIM( REGEXEXTRACT( raw!A29, ""(?s)●\s*조리 방법(.*)"" ) ) "),"1. 감자를 삶는다. 2. 관자는 물기를 제거하고, 올리브유는 냄비에 넣고 데운다. 3. 관자는 얇게 썰어두고, 살짝 감자를 강판에 간다 4. 볼에 다진 양상추, 단감, 고구마를 넣고 샐러드를 만든다. 5. 감자와 다진 양파로 전을 부친다. 6. 달군 올리브유를 관자에 부어 익힌다. 7. 접시에 감자양파전, 샐러드, 관자를 얹어 낸다.") -> 1. 감자를 삶는다. 2. 관자는 물기를 제거하고, 올리브유는 냄비에 넣고 데운다. 3. 관자는 얇게 썰어두고, 살짝 감자를 강판에 간다 4. 볼에 다진 양상추, 단감, 고구마를 넣고 샐러드를 만든다. 5. 감자와 다진 양파로 전을 부친다. 6. 달군 올리브유를 관자에 부어 익힌다. 7. 접시에 감자양파전, 샐러드, 관자를 얹어 낸다.
A30: =recipe!C30 -> 파티비프 | B30: =IFERROR(__xludf.DUMMYFUNCTION("TRIM( REGEXEXTRACT( raw!A30, ""(?s)●\s*조리 방법(.*)"" ) ) "),"1. 청고추에 칼집을 내고 그릴팬에 굽는다. 2. 고기와 양파는 채썰고 양송이 버섯도 편으로 썰어 팬에 볶는다. 3. 2에 고기에 쌈장과 생크림을 넣고 볶는다. 4. 3에 다진 총각김치를 넣고 후추를 뿌린다. 5. 접시에 밥을 놓고 주위에 볶은 고기를 얹는다. 6. 중앙에 총각김치를 올린다.") -> 1. 청고추에 칼집을 내고 그릴팬에 굽는다. 2. 고기와 양파는 채썰고 양송이 버섯도 편으로 썰어 팬에 볶는다. 3. 2에 고기에 쌈장과 생크림을 넣고 볶는다. 4. 3에 다진 총각김치를 넣고 후추를 뿌린다. 5. 접시에 밥을 놓고 주위에 볶은 고기를 얹는다. 6. 중앙에 총각김치를 올린다.
A31: =recipe!C31 -> 아이러브유부 | B31: =IFERROR(__xludf.DUMMYFUNCTION("TRIM( REGEXEXTRACT( raw!A31, ""(?s)●\s*조리 방법(.*)"" ) ) "),"1. 삼겹살, 생크림, 달걀 흰자, 마늘 2쪽을 믹서기에 넣고 간다. 2. 간 고기에 잣, 두반장, 굴소스를 넣고 섞는다. 3. 양파와 물에 씻은 고추장아찌를 다져 섞는다. 4. 유부의 속을 채우고 삶는다. 5. 고추 장아찌 국물과 핫소스, 볶은 다진 마늘을 섞어 소스를 만들어 함께 낸다.") -> 1. 삼겹살, 생크림, 달걀 흰자, 마늘 2쪽을 믹서기에 넣고 간다. 2. 간 고기에 잣, 두반장, 굴소스를 넣고 섞는다. 3. 양파와 물에 씻은 고추장아찌를 다져 섞는다. 4. 유부의 속을 채우고 삶는다. 5. 고추 장아찌 국물과 핫소스, 볶은 다진 마늘을 섞어 소스를 만들어 함께 낸다.
A32: =recipe!C32 -> 곤약 봉골레 곤봉 | B32: =IFERROR(__xludf.DUMMYFUNCTION("TRIM( REGEXEXTRACT( raw!A32, ""(?s)●\s*조리 방법(.*)"" ) ) "),"1. 가스레인지 위에 파프리카를 올리고 표면을 태운다. 2. 곤약을 얇게 국수처럼 썬다. (실곤약 대체 가능) 3. 바지락 반은 육수를 내고 반은 살을 발라둔다. 4. 표면을 태운 파프리카의 껍질을 벗기고 얇게 채썬다. 5. 올리브유에 다진 마늘을 볶다가 바지락과 소금 후추를 뿌리고 볶는다. 6. 채 썬 곤약과 파프리카를 넣어 볶다가 육수를 부어 끓인다.") -> 1. 가스레인지 위에 파프리카를 올리고 표면을 태운다. 2. 곤약을 얇게 국수처럼 썬다. (실곤약 대체 가능) 3. 바지락 반은 육수를 내고 반은 살을 발라둔다. 4. 표면을 태운 파프리카의 껍질을 벗기고 얇게 채썬다. 5. 올리브유에 다진 마늘을 볶다가 바지락과 소금 후추를 뿌리고 볶는다. 6. 채 썬 곤약과 파프리카를 넣어 볶다가 육수를 부어 끓인다.
A33: =recipe!C33 -> 렛잇컵 | B33: =IFERROR(__xludf.DUMMYFUNCTION("TRIM( REGEXEXTRACT( raw!A33, ""(?s)●\s*조리 방법(.*)"" ) ) "),"1. 찐 고구마의 껍질을 벗기고 으깬 후, 두유를 섞어 농도를 맞춘다. 2. 각종 과일을 먹기 좋은 크기로 썰어 둔다. 3. 와인잔에 찐 고구마와 과일을 겹겹이 쌓는다. 4. 플레인 요거트와 복분자 원액을 넣는다. 5. 생고구마를 썰어 스틱을 만들고 홍시와 플레인 요거트로 소스을 만들어 함께 낸다.") -> 1. 찐 고구마의 껍질을 벗기고 으깬 후, 두유를 섞어 농도를 맞춘다. 2. 각종 과일을 먹기 좋은 크기로 썰어 둔다. 3. 와인잔에 찐 고구마와 과일을 겹겹이 쌓는다. 4. 플레인 요거트와 복분자 원액을 넣는다. 5. 생고구마를 썰어 스틱을 만들고 홍시와 플레인 요거트로 소스을 만들어 함께 낸다.
A34: =recipe!C34 -> 마이 러블리 튀밥 | B34: =IFERROR(__xludf.DUMMYFUNCTION("TRIM( REGEXEXTRACT( raw!A34, ""(?s)●\s*조리 방법(.*)"" ) ) "),"1. 파프리카, 버섯, 양파를 다지고 올리브유를 두른 팬에 볶는다. 2. 명란젓에 다진 대파를 넣고, 볶은 채소, 즉석밥, 참기름을 넣고 함께 섞는다. 3. 팬에 올리브유와 마늘, 블랙올리브, 홍고추, 방울토마토, 토마토 소스를 넣어 소스를 만든다. 4. 밥을 뭉칠 때 속에 치즈를 넣고 밀가루, 달걀물, 빵가루 순으로 옷을 입힌다. 5. 달군 기름에 뭉친 밥을 넣어 튀긴다. 6. 토마토소스 위에 튀긴 밥을 올리고 파슬리와 올리브유를 뿌려서 낸다.") -> 1. 파프리카, 버섯, 양파를 다지고 올리브유를 두른 팬에 볶는다. 2. 명란젓에 다진 대파를 넣고, 볶은 채소, 즉석밥, 참기름을 넣고 함께 섞는다. 3. 팬에 올리브유와 마늘, 블랙올리브, 홍고추, 방울토마토, 토마토 소스를 넣어 소스를 만든다. 4. 밥을 뭉칠 때 속에 치즈를 넣고 밀가루, 달걀물, 빵가루 순으로 옷을 입힌다. 5. 달군 기름에 뭉친 밥을 넣어 튀긴다. 6. 토마토소스 위에 튀긴 밥을 올리고 파슬리와 올리브유를 뿌려서 낸다.
A35: =recipe!C35 -> 자투리타타 | B35: =IFERROR(__xludf.DUMMYFUNCTION("TRIM( REGEXEXTRACT( raw!A35, ""(?s)●\s*조리 방법(.*)"" ) ) "),"1. 파프리카, 양파, 버섯 등의 재료는 잘게 다진다. 2. 명란젓을 넣은 달걀물에 치즈를 갈아 넣는다. 3. 올리브유를 두른 팬에 다진 채소와 방울토마토, 다진 마늘, 팽이버섯을 넣고 볶는다. 4. 채소를 볶던 팬에 달걀물을 붓고 호일을 덮어 익힌다. 5. 베이컨을 잘게 썰어 키친타올 사이에 넣고 렌지에 돌려 바삭하게 만든다. 6. 프리타타 위에 베이컨을 놓고 토치로 표면을 익힌다.") -> 1. 파프리카, 양파, 버섯 등의 재료는 잘게 다진다. 2. 명란젓을 넣은 달걀물에 치즈를 갈아 넣는다. 3. 올리브유를 두른 팬에 다진 채소와 방울토마토, 다진 마늘, 팽이버섯을 넣고 볶는다. 4. 채소를 볶던 팬에 달걀물을 붓고 호일을 덮어 익힌다. 5. 베이컨을 잘게 썰어 키친타올 사이에 넣고 렌지에 돌려 바삭하게 만든다. 6. 프리타타 위에 베이컨을 놓고 토치로 표면을 익힌다.
A36: =recipe!C36 -> 괜찮아, 목심이야 | B36: =IFERROR(__xludf.DUMMYFUNCTION("TRIM( REGEXEXTRACT( raw!A36, ""(?s)●\s*조리 방법(.*)"" ) ) "),"1. 양파, 당근, 사과, 양상추를 가늘게 채 썬다. 2. 오리엔탈 소스에 식초와 설탕을 넣어 끓인 후, 채 썬 양파, 당근과 섞어둔다. 3. 소금, 후추로 밑간을 한 돼지고기 목심을 전분이 고르게 묻도록 섞는다. 4. 끓는 물에 돼지고기 목심을 익힌 후, 건진다. 5. 접시에 고기와 채소를 차례로 얹는다. 6. 채 썬 양상추와 사과를 올리고 소스를 뿌려 완성한다.") -> 1. 양파, 당근, 사과, 양상추를 가늘게 채 썬다. 2. 오리엔탈 소스에 식초와 설탕을 넣어 끓인 후, 채 썬 양파, 당근과 섞어둔다. 3. 소금, 후추로 밑간을 한 돼지고기 목심을 전분이 고르게 묻도록 섞는다. 4. 끓는 물에 돼지고기 목심을 익힌 후, 건진다. 5. 접시에 고기와 채소를 차례로 얹는다. 6. 채 썬 양상추와 사과를 올리고 소스를 뿌려 완성한다.
A37: =recipe!C37 -> 마이 스위트 베이비 | B37: =IFERROR(__xludf.DUMMYFUNCTION("TRIM( REGEXEXTRACT( raw!A37, ""(?s)●\s*조리 방법(.*)"" ) ) "),"1. 소금, 후추 간을 한 소고기 등심을 팬에 굽는다. 2. 사과를 자르고 씨를 발라 팬에 굽는다. 3. 소고기 등심을 꺼내 놓고 흑설탕과 물에 구운 사과를 졸인다. 4. 등심을 다시 팬에 올리고 레드와인을 부어 좀 더 익힌다. 5. 졸인 사과와 등심을 함께 낸다") -> 1. 소금, 후추 간을 한 소고기 등심을 팬에 굽는다. 2. 사과를 자르고 씨를 발라 팬에 굽는다. 3. 소고기 등심을 꺼내 놓고 흑설탕과 물에 구운 사과를 졸인다. 4. 등심을 다시 팬에 올리고 레드와인을 부어 좀 더 익힌다. 5. 졸인 사과와 등심을 함께 낸다
A38: =recipe!C38 -> 어란대첩 | B38: =IFERROR(__xludf.DUMMYFUNCTION("TRIM( REGEXEXTRACT( raw!A38, ""(?s)●\s*조리 방법(.*)"" ) ) "),"1. 무를 얇게 채 썬다. 2. 채 썬 무를 얼음물에 담가 식감을 살린다. 3. 끓는 물에 파스타면을 넣고 삶는다. 4. 익은 파스타면을 얼음물에 넣어 식힌 후 올리브유, 쯔유, 소금, 후추를 넣어 섞는다. 5. 접시에 파스타면과 채썬 무를 차례로 올리고 어란을 갈아 올린다.") -> 1. 무를 얇게 채 썬다. 2. 채 썬 무를 얼음물에 담가 식감을 살린다. 3. 끓는 물에 파스타면을 넣고 삶는다. 4. 익은 파스타면을 얼음물에 넣어 식힌 후 올리브유, 쯔유, 소금, 후추를 넣어 섞는다. 5. 접시에 파스타면과 채썬 무를 차례로 올리고 어란을 갈아 올린다.
A39: =recipe!C39 -> 뉴타운 달팽이 | B39: =IFERROR(__xludf.DUMMYFUNCTION("TRIM( REGEXEXTRACT( raw!A39, ""(?s)●\s*조리 방법(.*)"" ) ) "),"1. 팬에 버터, 다진 양파, 소금, 달팽이를 넣고 볶는다. 2. 끓는 물에 매시드 포테이토 분말을 넣고 매시드 포테이토를 만든다. 3. 달팽이를 볶던 팬에 레드와인을 부어 졸인다. 4. 팬에 버터와 시금치를 넣어 볶는다. 5. 접시에 매시드 포테이토를 깔고 달팽이와 양파를 올린 후, 볶은 시금치와 소스를 곁들여 낸다. 6. 마지막으로 다진 홍고추를 올린다.") -> 1. 팬에 버터, 다진 양파, 소금, 달팽이를 넣고 볶는다. 2. 끓는 물에 매시드 포테이토 분말을 넣고 매시드 포테이토를 만든다. 3. 달팽이를 볶던 팬에 레드와인을 부어 졸인다. 4. 팬에 버터와 시금치를 넣어 볶는다. 5. 접시에 매시드 포테이토를 깔고 달팽이와 양파를 올린 후, 볶은 시금치와 소스를 곁들여 낸다. 6. 마지막으로 다진 홍고추를 올린다.
A40: =recipe!C40 -> 삼국회담 | B40: =IFERROR(__xludf.DUMMYFUNCTION("TRIM( REGEXEXTRACT( raw!A40, ""(?s)●\s*조리 방법(.*)"" ) ) "),"1. 끓는 물에 쌀국수면을 삶는다. 2. 후추를 뿌린 양갈비를 손질한 후, 커민으로 양념을 한다. 3. 올리브유를 두른 팬에 으깬 마늘과 중국 고추소스를 넣어 볶다가 양갈비를 넣어 굽는다. 4. 믹서기에 코코넛 밀크와 새우젓, 말린 양파를 넣고 갈아 소스를 만든다. 5. 끓인 쌀국수 면을 건져 얼음물에 헹군 후 피쉬소스, 동치미 국물, 탄산수, 참기름을 넣어 국수를 완성한다. 6. 접시에 구운 양갈비와 새우젓 소스를 곁들여 낸다.") -> 1. 끓는 물에 쌀국수면을 삶는다. 2. 후추를 뿌린 양갈비를 손질한 후, 커민으로 양념을 한다. 3. 올리브유를 두른 팬에 으깬 마늘과 중국 고추소스를 넣어 볶다가 양갈비를 넣어 굽는다. 4. 믹서기에 코코넛 밀크와 새우젓, 말린 양파를 넣고 갈아 소스를 만든다. 5. 끓인 쌀국수 면을 건져 얼음물에 헹군 후 피쉬소스, 동치미 국물, 탄산수, 참기름을 넣어 국수를 완성한다. 6. 접시에 구운 양갈비와 새우젓 소스를 곁들여 낸다.
...

Sheet recipe_ingredient
A1: recipe_ingredient | B1: ingredient_name
A2: =IFERROR(__xludf.DUMMYFUNCTION("ARRAYFORMULA( QUERY( SPLIT( FLATTEN( ingredient!A2:A17495 & ""♦"" & TRIM(SPLIT(ingredient!B2:B17495, "","")) ), ""♦"" ), ""where Col1 is not null and Col2 is not null"", 0 ) ) "),"치킨 밀푀유") -> 치킨 밀푀유 | B2: =IFERROR(__xludf.DUMMYFUNCTION("""COMPUTED_VALUE"""),"닭가슴살") -> 닭가슴살
A3: =IFERROR(__xludf.DUMMYFUNCTION("""COMPUTED_VALUE"""),"치킨 밀푀유") -> 치킨 밀푀유 | B3: =IFERROR(__xludf.DUMMYFUNCTION("""COMPUTED_VALUE"""),"슬라이스햄") -> 슬라이스햄
A4: =IFERROR(__xludf.DUMMYFUNCTION("""COMPUTED_VALUE"""),"치킨 밀푀유") -> 치킨 밀푀유 | B4: =IFERROR(__xludf.DUMMYFUNCTION("""COMPUTED_VALUE"""),"양파") -> 양파
A5: =IFERROR(__xludf.DUMMYFUNCTION("""COMPUTED_VALUE"""),"치킨 밀푀유") -> 치킨 밀푀유 | B5: =IFERROR(__xludf.DUMMYFUNCTION("""COMPUTED_VALUE"""),"양배추") -> 양배추
A6: =IFERROR(__xludf.DUMMYFUNCTION("""COMPUTED_VALUE"""),"치킨 밀푀유") -> 치킨 밀푀유 | B6: =IFERROR(__xludf.DUMMYFUNCTION("""COMPUTED_VALUE"""),"파프리카") -> 파프리카
A7: =IFERROR(__xludf.DUMMYFUNCTION("""COMPUTED_VALUE"""),"치킨 밀푀유") -> 치킨 밀푀유 | B7: =IFERROR(__xludf.DUMMYFUNCTION("""COMPUTED_VALUE"""),"바게트") -> 바게트
A8: =IFERROR(__xludf.DUMMYFUNCTION("""COMPUTED_VALUE"""),"치킨 밀푀유") -> 치킨 밀푀유 | B8: =IFERROR(__xludf.DUMMYFUNCTION("""COMPUTED_VALUE"""),"다진마늘") -> 다진마늘
A9: =IFERROR(__xludf.DUMMYFUNCTION("""COMPUTED_VALUE"""),"치킨 밀푀유") -> 치킨 밀푀유 | B9: =IFERROR(__xludf.DUMMYFUNCTION("""COMPUTED_VALUE"""),"크림소스") -> 크림소스
A10: =IFERROR(__xludf.DUMMYFUNCTION("""COMPUTED_VALUE"""),"치킨 밀푀유") -> 치킨 밀푀유 | B10: =IFERROR(__xludf.DUMMYFUNCTION("""COMPUTED_VALUE"""),"우유") -> 우유
A11: =IFERROR(__xludf.DUMMYFUNCTION("""COMPUTED_VALUE"""),"치킨 밀푀유") -> 치킨 밀푀유 | B11: =IFERROR(__xludf.DUMMYFUNCTION("""COMPUTED_VALUE"""),"통후추") -> 통후추
A12: =IFERROR(__xludf.DUMMYFUNCTION("""COMPUTED_VALUE"""),"치킨 밀푀유") -> 치킨 밀푀유 | B12: =IFERROR(__xludf.DUMMYFUNCTION("""COMPUTED_VALUE"""),"소금") -> 소금
A13: =IFERROR(__xludf.DUMMYFUNCTION("""COMPUTED_VALUE"""),"치킨 밀푀유") -> 치킨 밀푀유 | B13: =IFERROR(__xludf.DUMMYFUNCTION("""COMPUTED_VALUE"""),"토마토소스") -> 토마토소스
A14: =IFERROR(__xludf.DUMMYFUNCTION("""COMPUTED_VALUE"""),"취닭거리") -> 취닭거리 | B14: =IFERROR(__xludf.DUMMYFUNCTION("""COMPUTED_VALUE"""),"닭죽") -> 닭죽
A15: =IFERROR(__xludf.DUMMYFUNCTION("""COMPUTED_VALUE"""),"취닭거리") -> 취닭거리 | B15: =IFERROR(__xludf.DUMMYFUNCTION("""COMPUTED_VALUE"""),"라조장") -> 라조장
A16: =IFERROR(__xludf.DUMMYFUNCTION("""COMPUTED_VALUE"""),"취닭거리") -> 취닭거리 | B16: =IFERROR(__xludf.DUMMYFUNCTION("""COMPUTED_VALUE"""),"취두부") -> 취두부
A17: =IFERROR(__xludf.DUMMYFUNCTION("""COMPUTED_VALUE"""),"취닭거리") -> 취닭거리 | B17: =IFERROR(__xludf.DUMMYFUNCTION("""COMPUTED_VALUE"""),"족발") -> 족발
A18: =IFERROR(__xludf.DUMMYFUNCTION("""COMPUTED_VALUE"""),"취닭거리") -> 취닭거리 | B18: =IFERROR(__xludf.DUMMYFUNCTION("""COMPUTED_VALUE"""),"버터") -> 버터
A19: =IFERROR(__xludf.DUMMYFUNCTION("""COMPUTED_VALUE"""),"닭딸") -> 닭딸 | B19: =IFERROR(__xludf.DUMMYFUNCTION("""COMPUTED_VALUE"""),"복분자") -> 복분자
A20: =IFERROR(__xludf.DUMMYFUNCTION("""COMPUTED_VALUE"""),"닭딸") -> 닭딸 | B20: =IFERROR(__xludf.DUMMYFUNCTION("""COMPUTED_VALUE"""),"바게트") -> 바게트
A21: =IFERROR(__xludf.DUMMYFUNCTION("""COMPUTED_VALUE"""),"닭딸") -> 닭딸 | B21: =IFERROR(__xludf.DUMMYFUNCTION("""COMPUTED_VALUE"""),"닭가슴살") -> 닭가슴살
A22: =IFERROR(__xludf.DUMMYFUNCTION("""COMPUTED_VALUE"""),"닭딸") -> 닭딸 | B22: =IFERROR(__xludf.DUMMYFUNCTION("""COMPUTED_VALUE"""),"우유") -> 우유
A23: =IFERROR(__xludf.DUMMYFUNCTION("""COMPUTED_VALUE"""),"닭딸") -> 닭딸 | B23: =IFERROR(__xludf.DUMMYFUNCTION("""COMPUTED_VALUE"""),"레몬즙") -> 레몬즙
A24: =IFERROR(__xludf.DUMMYFUNCTION("""COMPUTED_VALUE"""),"닭딸") -> 닭딸 | B24: =IFERROR(__xludf.DUMMYFUNCTION("""COMPUTED_VALUE"""),"소금") -> 소금
A25: =IFERROR(__xludf.DUMMYFUNCTION("""COMPUTED_VALUE"""),"닭딸") -> 닭딸 | B25: =IFERROR(__xludf.DUMMYFUNCTION("""COMPUTED_VALUE"""),"후추") -> 후추
A26: =IFERROR(__xludf.DUMMYFUNCTION("""COMPUTED_VALUE"""),"닭딸") -> 닭딸 | B26: =IFERROR(__xludf.DUMMYFUNCTION("""COMPUTED_VALUE"""),"마늘") -> 마늘
A27: =IFERROR(__xludf.DUMMYFUNCTION("""COMPUTED_VALUE"""),"어머니 맛 풍족밥") -> 어머니 맛 풍족밥 | B27: =IFERROR(__xludf.DUMMYFUNCTION("""COMPUTED_VALUE"""),"치킨") -> 치킨
A28: =IFERROR(__xludf.DUMMYFUNCTION("""COMPUTED_VALUE"""),"어머니 맛 풍족밥") -> 어머니 맛 풍족밥 | B28: =IFERROR(__xludf.DUMMYFUNCTION("""COMPUTED_VALUE"""),"족발") -> 족발
A29: =IFERROR(__xludf.DUMMYFUNCTION("""COMPUTED_VALUE"""),"어머니 맛 풍족밥") -> 어머니 맛 풍족밥 | B29: =IFERROR(__xludf.DUMMYFUNCTION("""COMPUTED_VALUE"""),"두반장") -> 두반장
A30: =IFERROR(__xludf.DUMMYFUNCTION("""COMPUTED_VALUE"""),"어머니 맛 풍족밥") -> 어머니 맛 풍족밥 | B30: =IFERROR(__xludf.DUMMYFUNCTION("""COMPUTED_VALUE"""),"라조장") -> 라조장
A31: =IFERROR(__xludf.DUMMYFUNCTION("""COMPUTED_VALUE"""),"어머니 맛 풍족밥") -> 어머니 맛 풍족밥 | B31: =IFERROR(__xludf.DUMMYFUNCTION("""COMPUTED_VALUE"""),"유자청") -> 유자청
A32: =IFERROR(__xludf.DUMMYFUNCTION("""COMPUTED_VALUE"""),"어머니 맛 풍족밥") -> 어머니 맛 풍족밥 | B32: =IFERROR(__xludf.DUMMYFUNCTION("""COMPUTED_VALUE"""),"밀가루") -> 밀가루
A33: =IFERROR(__xludf.DUMMYFUNCTION("""COMPUTED_VALUE"""),"어머니 맛 풍족밥") -> 어머니 맛 풍족밥 | B33: =IFERROR(__xludf.DUMMYFUNCTION("""COMPUTED_VALUE"""),"밥") -> 밥
A34: =IFERROR(__xludf.DUMMYFUNCTION("""COMPUTED_VALUE"""),"치킨 요로케") -> 치킨 요로케 | B34: =IFERROR(__xludf.DUMMYFUNCTION("""COMPUTED_VALUE"""),"닭가슴살") -> 닭가슴살
A35: =IFERROR(__xludf.DUMMYFUNCTION("""COMPUTED_VALUE"""),"치킨 요로케") -> 치킨 요로케 | B35: =IFERROR(__xludf.DUMMYFUNCTION("""COMPUTED_VALUE"""),"소금") -> 소금
A36: =IFERROR(__xludf.DUMMYFUNCTION("""COMPUTED_VALUE"""),"치킨 요로케") -> 치킨 요로케 | B36: =IFERROR(__xludf.DUMMYFUNCTION("""COMPUTED_VALUE"""),"후추") -> 후추
A37: =IFERROR(__xludf.DUMMYFUNCTION("""COMPUTED_VALUE"""),"치킨 요로케") -> 치킨 요로케 | B37: =IFERROR(__xludf.DUMMYFUNCTION("""COMPUTED_VALUE"""),"밀가루") -> 밀가루
A38: =IFERROR(__xludf.DUMMYFUNCTION("""COMPUTED_VALUE"""),"치킨 요로케") -> 치킨 요로케 | B38: =IFERROR(__xludf.DUMMYFUNCTION("""COMPUTED_VALUE"""),"양파") -> 양파
A39: =IFERROR(__xludf.DUMMYFUNCTION("""COMPUTED_VALUE"""),"치킨 요로케") -> 치킨 요로케 | B39: =IFERROR(__xludf.DUMMYFUNCTION("""COMPUTED_VALUE"""),"햄") -> 햄
A40: =IFERROR(__xludf.DUMMYFUNCTION("""COMPUTED_VALUE"""),"치킨 요로케") -> 치킨 요로케 | B40: =IFERROR(__xludf.DUMMYFUNCTION("""COMPUTED_VALUE"""),"토마토 소스") -> 토마토 소스
...

Sheet category
A1: recipe_title | B1: category
A2: =recipe!C2 -> 치킨 밀푀유
A3: =recipe!C3 -> 취닭거리
A4: =recipe!C4 -> 닭딸
A5: =recipe!C5 -> 어머니 맛 풍족밥
A6: =recipe!C6 -> 치킨 요로케
A7: =recipe!C7 -> 포크 미트볼
A8: =recipe!C8 -> 만두부인 육수터졌네
A9: =recipe!C9 -> 심쿵 오믈렛
A10: =recipe!C10 -> 엔초비 파스타
A11: =recipe!C11 -> 고기와 썸타는 떡국떡 삼합
A12: =recipe!C12 -> 와닭
A13: =recipe!C13 -> 브로콜리 치킨
... A1019: =recipe!C1019 -> 만두 만두 만두 눈꽃만두♬
